Workbook
Name Wb_d: _xlfn.LAMBDA(_xlpm.D,_xlpm.H,(0.00893*(((_xlpm.D^2)*_xlpm.H))^0.977))
Name Wb_de: _xlfn.LAMBDA(_xlpm.D,_xlpm.H,(0.00349*(((_xlpm.D^2)*_xlpm.H)^1.03)))
Name Wb_e: _xlfn.LAMBDA(_xlpm.D,_xlpm.H,(0.006003*(((_xlpm.D^2)*_xlpm.H))^1.027))
Name Wb_m: _xlfn.LAMBDA(_xlpm.D,_xlpm.H,(0.01579*(((_xlpm.D^2)*_xlpm.H))^0.9124))
Name Wb_n: _xlfn.LAMBDA(_xlpm.D,_xlpm.H,(0.00349*(((_xlpm.D^2)*_xlpm.H))^1.03))
Name Wl_d: _xlfn.LAMBDA(_xlpm.D,_xlpm.H,(0.014*(((_xlpm.D^2)*_xlpm.H))^0.669))
Name Wl_de: _xlfn.LAMBDA(_xlpm.Ws,_xlpm.Wb,(1/((28/(_xlpm.Ws+_xlpm.Wb))+0.025)))
Name Wl_e: _xlfn.LAMBDA(_xlpm.Ws,_xlpm.Wb,(1/((28/(_xlpm.Ws+_xlpm.Wb))+0.025)))
Name Wl_m: _xlfn.LAMBDA(_xlpm.D,_xlpm.H,(0.0678*(((_xlpm.D^2)*_xlpm.H))^0.5806))
Name Wl_n: _xlfn.LAMBDA(_xlpm.Ws,_xlpm.Wb,(1/((28/(_xlpm.Ws+_xlpm.Wb))+0.025)))
Name Ws_d: _xlfn.LAMBDA(_xlpm.D,_xlpm.H,(0.0509*(((_xlpm.D^2)*_xlpm.H))^0.919))
Name Ws_de: _xlfn.LAMBDA(_xlpm.D,_xlpm.H,(0.0396*(((_xlpm.D^2)*_xlpm.H)^0.933)))
Name Ws_e: _xlfn.LAMBDA(_xlpm.D,_xlpm.H,(0.0396*(((_xlpm.D^2)*_xlpm.H))^0.9326))
Name Ws_m: _xlfn.LAMBDA(_xlpm.D,_xlpm.H,(0.05466*(((_xlpm.D^2)*_xlpm.H))^0.945))
Name Ws_n: _xlfn.LAMBDA(_xlpm.D,_xlpm.H,(0.0396*(((_xlpm.D^2)*_xlpm.H))^0.933))
Name Wt: _xlfn.LAMBDA(_xlpm.Ws,_xlpm.Wb,_xlpm.Wl,(_xlpm.Ws+_xlpm.Wb+_xlpm.Wl))

Sheet คู่มือการใช้งาน
B1: ในเอกสารประกอบด้วยสัญลักษณ์สีดังนี้
B2: สี | D2: ความหมาย
D3: หัวข้อ
D4: ข้อมูลอัตโนมัติ (ดึงข้อมูล / คำนวณให้อัตโนมัติ) กรอกข้อมูลทับได้
D5: เกณฑ์วิเคราะห์กลุ่ม "ระบบนิเวศ"
D6: เกณฑ์วิเคราะห์กลุ่ม "ผลประโยชน์ร่วม"
D7: เกณฑ์วิเคราะห์กลุ่ม "การจัดการพื้นที่สีเขียว"
D8: บันทึกคำตอบ โดยเลือก จากตัวเลือก (drop down list)
D9: บันทึกคำตอบ / ข้อมูลต่าง ๆ ในช่องสีขาว
D10: ไม่ต้องบันทึกข้อมูล
B13: แผ่นงาน (sheet) ในการวิเคราะห์/ประเมิน | D13: ความหมาย
B14: 1 สรุปข้อมูลพื้นฐาน | D14: ข้อมูลพื้นฐานของพื้นที่สีเขียวของหน่วยงานที่ทำการวิเคราะห์ | E14: ประกอบการคิดค่า สำหรับประเมินตัวชี้วัดที่ 1.1
B15: 2 ขนาดพื้นที่ต่างๆ | D15: สำหรับกรอกข้อมูลขนาดพื้นที่ทั้งหมดของหน่วยงาน, ขนาดพื้นที่ปลูกพืชนอกอาคาร, พื้นที่สวนดาดฟ้า/สวนหลังคา, และขนาดพื้นที่แหล่งน้ำ | E15: ประกอบการคิดค่า สำหรับประเมินตัวชี้วัดที่ 1.1 และ 1.5
B16: 3 พื้นที่เรือนยอดปกคลุม | D16: สำหรับกรอกข้อมูลพื้นที่เรือนยอดปกคลุมของไม้ต้น ปาล์ม และไผ่ | E16: ประกอบการคิดค่า สำหรับประเมินตัวชี้วัดที่ 2.2
B17: 4 ข้อมูลต้นไม้ (ปัจจุบัน) | D17: สำหรับกรอกข้อมูลต้นไม้ที่บันทึกจากภาคสนาม ในปี พ.ศ. ปัจจุบัน | E17: ประกอบการคิดค่า สำหรับประเมินตัวชี้วัดที่ 2.1 | G17: สามารถพิมพ์ ตารางบันทึกข้อมูลต้นไม้ จากแผ่นงาน "Printบันทึกข้อมูลพืชภาคสนาม"
B18: 5 ข้อมูลต้นไม้ (ปีฐาน) | D18: สำหรับกรอกข้อมูลต้นไม้ที่บันทึกจากภาคสนาม ในปีฐาน (ย้อนหลังอย่างน้อย 1 ปี) | E18: ประกอบการคิดค่า สำหรับประเมินตัวชี้วัดที่ 2.1
B19: 6 การวิเคราะห์ตนเอง | D19: สำหรับกรอกข้อมูลเพื่อวิเคราะห์ตนเอง ตามเกณฑ์การให้คะแนนที่กำหนด (บางข้อคำนวณให้อัตโนมัติ)
B20: 7 สรุปการประเมิน | D20: ดูผลการประเมิน
B23: ขั้นตอนในการวิเคราะห์/ประเมิน / ใช้แผ่นงาน | D23: ข้อแนะนำ / การได้มาซึ่งข้อมูลสำหรับการวิเคราะห์ศักยภาพฯ | E23: หมายเหตุ
A24: 1 | B24: บันทึกไฟล์ใหม่ (save as) จากไฟล์เทมเพลต (template) | D24: Save as/ บันทึกเป็น : แนะนำให้ตั้งเป็น "ชื่อหน่วยงาน_จังหวัด_yyyymmdd" | E24: ควรสร้างโฟลเดอร์ใหม่ เพื่อจัดเก็บข้อมูลที่เกี่ยวข้อง
A26: 2 | B26: บันทึกข้อมูลพื้นฐานของพื้นที่ ข้อ 1-6 (แผ่นงานที่ "1สรุปข้อมูลพื้นฐาน")
B27: 1 วัน เวลา ที่ประเมิน | D27: กรอกวัน-เดือน-ปี ค.ศ. ที่ประเมิน เช่น 24/12/2567
B28: 2 ชื่อพื้นที่สีเขียว | D28: กรอกข้อมูลตามรายละเอียดของหน่วยงาน
B29: 3 ผู้บันทึกข้อมูล | D29: กรอกชื่อผู้บันทึกข้อมูล อาจมีมากกว่า 1 คน เพื่อประโยชน์ในการติดตาม หากมีการเปลี่ยนผู้รับผิดชอบ
B30: 4 หน่วยงานรับผิดชอบพื้นที่ | D30: กรอกชื่อหน่วยงานรับผิดชอบพื้นที่ เช่น อบต.aa, โรงรียน bb, โรงาน cc เป็นต้น
B31: 5 พิกัดของพื้นที่สีเขียว | D31: พิกัดของพื้นที่สีเขียวของหน่วยงาน (บริเวณกลางพื้นที่ 1 ตำแหน่ง )
D32: ใช้เครื่องมือปักหมุด ใน Google Earth Pro
D33: ปักหมุด เลื่อนตำแหน่งที่ต้องการ ตั้งชื่อ นำข้อมูลไปกรอกในแผ่นงานที่ 1
B53: 6 ประเภทของพื้นที่ (1 ใน 6 รูปแบบ) | D53: เลือก ประเภทของพื้นที่สีเขียวจากรายการ 1 ประเภทเท่านั้น | E53: ดูรายละเอียด และตัวอย่างเพิ่มเติม "ประเภทของพื้นที่สีเขียวในเมือง 6 ประเภท" จากเอกสารคู่มือเกณฑ์วิเคราะห์ศักยภาพฯ
E82: ศึกษาการใช้ Google Earth Pro ได้จากคู่มือบทที่ 3
E83: https://www.rspgchula.sc.chula.ac.th/book/PDFหนังสือ/Book-GPS.pdf
A85: 3 | B85: บันทึกขนาดและประเภทพื้นที่ย่อยที่พบในพื้นที่หน่วยงาน | D85: สร้าง “รูปหลายเหลี่ยม/Polygon” ในโปรแกรม Google Earth Pro
B86: (แผ่นงาน "2ขนาดพื้นที่ต่างๆ") | D86: สร้างขอบเขตพื้นที่ทั้งหมด / สร้างขอบเขตพื้นที่ปลูกพืชนอกอาคาร และพื้นที่สวนดาดฟ้า/สวนหลังคา | E86: เป็นพื้นที่ที่มีไม้ต้น (พืชที่มีเนื้อไม้ มีเส้นผ่านศูนย์กลางที่ระดับความสูงเพียงอก (130 ซม.จากระดับพื้นดิน หรือ Diameter at Breast Height: DBH) ตั้งแต่ 4.5 ซม. ขึ้นไป และมีความสูง ตั้งแต่ 1.3 ม. ขึ้นไป) เป็นองค์ประกอบ
D87: คลิกขวา เลือก Propoties / Measurements เลือกหน่วยเป็น ตารางเมตร
D88: นำขนาดพื้นที่หน่วยงาน ไปกรอกในแผ่นงาน “2ขนาดพื้นที่ต่างๆ” ช่อง B1
D89: นำขนาดพื้นที่อื่น ๆ ไปกรอก โดยเลือกประเภทพื้นที่ (B6 เป็นต้นไป) และกรอกขนาด (C6 เป็นต้นไป)
A155: 4 | B155: บันทึกขนาดพื้นที่ที่ไม้ต้น ปาล์ม ไผ่ ที่ปกคลุม (แผ่นงาน "3พื้นที่เรือนยอด") | D155: สร้าง “รูปหลายเหลี่ยม/Polygon” ของพื้นที่ที่มีการปกคลุมด้วยเรือนยอดของไม้ต้น ปาล์ม และไผ่ ด้วยวิธีเดียวกับข้างต้น
D156: นำข้อมูลไปกรอกในแผ่นงาน "3พื้นที่เรือนยอด"
A158: 5 | B158: บันทึกข้อมูลพืชในภาคสนาม (ชนิด เส้นรอบวง ความสูง และข้อมูลอื่น ๆ) และ สำรวจวิสัยของพืชที่พบในพื้นที่ พร้อมกับถ่ายภาพประกอบ | D158: พริ้นท์ แผ่นงาน "Printบันทึกข้อมูลพืชภาคสนาม" สำหรับนำไปกรอกข้อมูลภาคสนาม หรือจดลงโปรแกรมโดยตรงแบบออนไลน์ (ต้องอัพโหลดไฟล์สู่ระบบ cloud ก่อน) | E158: ศึกษารายละเอียดเพิ่มเติมได้ที่ :
D159: บันทึกข้อมูลต่าง ๆ โดยเฉพาะชื่อเส้นรอบวง และความสูง | E159: https://ghgreduction.tgo.or.th/th/download-less/100-less-management/1364-2020-09-23-10-21-08.html
...

Sheet 1สรุปข้อมูลพื้นฐาน
B1: Save As ไฟล์ "ชื่อหน่วยงาน_จังหวัด_yyyymmdd" จากนั้น กรอกข้อมูลข้อ 1-6 ในคอลัมน์ D
A2: ข้อ | B2: รายการ | C2: คำอธิบาย | D2: ข้อมูล | E2: หน่วย
A3: 1 | B3: วันที่ประเมิน | C3: บันทึก วันที่ประเมิน ในรูปแบบ วัน/เดือน/ค.ศ. เช่น 26/12/2024 | D3: 45652
A4: 2 | B4: ชื่อพื้นที่สีเขียว | C4: ชื่อเรียกของพื้นที่สีเขียว เช่น สวนป่าคาร์บอน, โรงเรียนคาร์บอน เป็นต้น
A5: 3 | B5: ผู้บันทึกข้อมูล (กรอกได้มากกว่า 1 คน เพื่อประโยชน์ในการติดตามตรวจสอบเมื่อเปลี่ยนผู้รับผิดชอบ (แทรกแถวเพิ่มได้)) | C5: ผู้บันทึกข้อมูลคนที่ 1:
C6: ผู้บันทึกข้อมูลคนที่ 2:
C7: ผู้บันทึกข้อมูลคนที่ 3
C8: ผู้บันทึกข้อมูลคนที่ 4
A9: 4 | B9: หน่วยงานรับผิดชอบพื้นที่ | C9: ชื่อหน่วยงานรับผิดชอบพื้นที่ เช่น โรงเรียน ก, วัด ข, อบต.ค,โรงงาน ง เป็นต้น
A10: 5 | B10: พิกัดของพื้นที่สีเขียวของหน่วยงาน | C10: บันทึกค่าละติจูด (latitude) ใจกลางของพื้นที่
B11: (บริเวณกลางพื้นที่ 1 ตำแหน่ง ) | C11: บันทึกค่าลองจิจูด (Longtitude) ใจกลางของพื้นที่
C12: หรือ บันทึกค่า UTM_X_E กลางของพื้นที่
C13: บันทึกค่า UTM_Y_N กลางของพื้นที่
C14: บันทึกค่า UTM_Zone
A15: 6 | B15: ประเภทของพื้นที่ (1 ใน 6 รูปแบบ) | C15: เลือก ประเภทของพื้นที่สีเขียวจากรายการ 1 ประเภทเท่านั้น
A17: 7 | B17: สรุปขนาดพื้นที่
B18: ขนาดพื้นที่ทั้งหมดของหน่วยงาน / project site | C18: ขนาดพื้นที่สีเขียวทั้งหมดของหน่วยงาน (ขนาด project site) | D18: =คำนวณ!B8 -> 0 | E18: ไร่
B19: ขนาดพื้นที่ปลูกพืชนอกอาคาร | C19: ขนาดพื้นที่ที่มีไม้ต้น (ที่มีเนื้อไม้) เป็นองค์ประกอบหลัก มีไม้พุ่ม และพืชพรรณอื่น ๆ เป็นองค์ประกอบรอง | D19: =คำนวณ!B2 -> ยังไม่บันทึกข้อมูล | E19: ไร่
B20: ขนาดพื้นที่สวนดาดฟ้า/หลังคา | C20: ขนาดพื้นที่ที่มีไม้ต้น (ที่มีเนื้อไม้) เป็นองค์ประกอบหลัก | D20: =คำนวณ!B3 -> ยังไม่บันทึกข้อมูล | E20: ไร่
B21: ขนาดพื้นที่สีเขียวรวม | C21: ขนาดพื้นที่ปลูกพืชนอกอาคาร + ขนาดพื้นที่สวนดาดฟ้า/หลังคา | D21: =คำนวณ!B4 -> #VALUE! | E21: ไร่
B22: ขนาดพื้นที่แหล่งน้ำ | C22: ขนาดพื้นที่แหล่งน้ำ ที่พบในพื้นที่สีเขียว | D22: =คำนวณ!B5 -> ยังไม่บันทึกข้อมูล | E22: ไร่
A23: 8 | B23: พืช
B24: ขนาดพื้นที่แปลงสุ่มตัวอย่างหรือพื้นที่สำรวจปีปัจจุบัน | C24: ขนาดพื้นที่แปลงสุ่มตัวอย่างหรือพื้นที่สำรวจต้นไม้ ในปีปัจจุบัน | D24: ='4ข้อมูลไม้ต้น (ปัจจุบัน)'!E3 -> 0 | E24: ไร่
B25: จำนวนไม้ต้นในแปลงสำรวจ | C25: จำนวนไม้ต้น (tree) ที่พบในพื้นที่ระหว่างการสำรวจ | D25: =คำนวณ!B73 -> 3 | E25: ต้น
B26: จำนวนไม้ต้นในพื้นที่สีเขียวทั้งหมด (ค่าคาดการณ์) | C26: จำนวนไม้ต้นในพื้นที่สีเขียวทั้งหมด (ค่าคาดการณ์ จากากรเทียบบัญญัติไตรยางค์) | D26: =IF(D18>0,(D21*D25)/D24,"ยังไม่ได้บันทึกข้อมูล แผ่นงานที่ 2") -> ยังไม่ได้บันทึกข้อมูล แผ่นงานที่ 2 | E26: ต้น
A27: 9 | B27: ข้อมูลเชิงปริมาณ
B28: ความหนาแน่นไม้ต้นในพื้นที่สีเขียวทั้งหมด | C28: ความหนาแน่นไม้ต้นในพื้นที่สีเขียวทั้งหมด | D28: =D26/D21 -> #VALUE! | E28: ต้น/ไร่
B29: ปริมาณการดูดซับคาร์บอนไดออกไซด์ (ไม้ต้น, ปีฐาน) | C29: ปริมาณการดูดซับ CO2 รวมของพื้นที่สีเขียว ที่เป็นไม้ต้น ปีฐาน | D29: =คำนวณ!C78 -> ไม่ถูกต้อง ยังไม่ได้กรอกขนาดพื้นที่ | E29: tCO2eq/ไร่ | F29: ใช้สมการ พรรณไม้ทั่วไป | G29: รายละเอียดในแผ่นงาน คู่มือการใช้งาน บรรทัดที่ 158 เป็นต้นไป
B30: ปริมาณการดูดซับคาร์บอนไดออกไซด์ (ไม้ต้น, ปีปัจจุบัน) | C30: ปริมาณการดูดซับ CO2 รวมของพื้นที่สีเขียว ที่เป็นไม้ต้น ปีปัจจุบัน | D30: =คำนวณ!C79 -> ไม่ถูกต้อง ยังไม่ได้กรอกขนาดพื้นที่ | E30: tCO2eq/ไร่
B31: ปริมาณการดูดซับคาร์บอนไดออกไซด์ ต่อปี (ไม้ต้น, การเพิ่มพูน) | C31: ปริมาณการดูดซับ CO2 รวมของพื้นที่สีเขียว เฉลี่ยต่อปี (การเพิ่มพูนการดูดซับฯ) | D31: =คำนวณ!$C$81 -> ยังไม่บันทึกข้อมูล | E31: tCO2eq/ไร่/ปี
B32: ขนาดพื้นที่เรือนยอดปกคลุมไม้ต้น (รวมปาล์ม ไผ่) | C32: พื้นที่ปกคลุมด้วยเรือนยอดไม้ต้น+ปาล์ม+ไผ่ ต่อพื้นที่สีเขียวทั้งหมด | D32: =คำนวณ!B7 -> 0 | E32: ไร่
B33: สัดส่วนต่าง ๆ
A34: 1.1 | B34: ตัวชี้วัด 1.1 สัดส่วนพื้นที่สีเขียวต่อพื้นที่ทั้งหมด | D34: =คำนวณ!B11 -> ยังไม่บันทึกข้อมูล
A35: 1.5 | B35: ตัวชี้วัด 1.5 สัดส่วนพื้นที่แหล่งน้ำต่อพื้นที่ทั้งหมด | D35: =คำนวณ!C12 -> ยังไม่บันทึกข้อมูล
A36: 2.2 | B36: ตัวชี้วัด 2.2 ปกคลุมเรือนยอด | D36: =คำนวณ!C14 -> #DIV/0!
A39: เพิ่มเติม | B39: ปริมาณการดูดซับคาร์บอนไดออกไซด์ (ไม้หนุ่ม, ปีฐาน) | C39: ปริมาณการดูดซับ CO2 รวมของพื้นที่สีเขียว ที่เป็นไม้ต้น ปีฐาน | D39: =คำนวณ!C83 -> ไม่ถูกต้อง ยังไม่ได้กรอกขนาดพื้นที่ | E39: tCO2eq/ไร่ | F39: ใช้สมการไม้หนุ่ม/กล้าไม้ | G39: ป่าชนิดอื่นๆ | H39: WS = 0.0702(D^2 H)^0.8737 | I39: ธิติ วิสารัตน์ และ ชลธิดา เชิญขุนทด (2547)
B40: ปริมาณการดูดซับคาร์บอนไดออกไซด์ (ไม้หนุ่ม, ปีปัจจุบัน) | C40: ปริมาณการดูดซับ CO2 รวมของพื้นที่สีเขียว ที่เป็นไม้ต้น ปีปัจจุบัน | D40: =คำนวณ!C84 -> ไม่ถูกต้อง ยังไม่ได้กรอกขนาดพื้นที่ | E40: tCO2eq/ไร่ | H40: WB = 0.0093(D^2 H)^0.9403
B41: ปริมาณการดูดซับคาร์บอนไดออกไซด์ ต่อปี (ไม้หนุ่ม, การเพิ่มพูน) | C41: ปริมาณการดูดซับ CO2 รวมของพื้นที่สีเขียว เฉลี่ยต่อปี (การเพิ่มพูนการดูดซับฯ) | D41: =คำนวณ!$C$86 -> ยังไม่บันทึกข้อมูล | E41: tCO2eq/ไร่/ปี | H41: WL = 0.0244(D^2 H)^1.0517
I42: ธิติ วิสารัตน์ และ ชลธิดา เชิญขุนทด. 2547. องค์ประกอบของชนิดพันธ์พืชและปริมาณมวลชีวภาพ เหนือพื้นดินของต้นไม้ในป่าดิบแล้ง.
F43: สามารถปรับเปลี่ยนสมการได้ ตามความเหมาะสม | I43: ในเอกสารการประชุม “การเปลี่ยนแปลงสภาพ ภูมิอากาศทางป่าไม้: ป่าไม้กับการเปลี่ยนแปลงสภาพภูมิอากาศ” ณ โรงแรมรามาการ์เด้น กรุงเทพฯ ระหว่างวันที่ 16-17 สิงหาคม 2547.

Sheet 2ขนาดพื้นที่ต่างๆ
A1: 1.กรอกข้อมูล ช่อง B1 : ขนาดพื้นที่หน่วยงานทั้งหมด | C1: ตารางเมตร | D1: หากนำตัวเลขจาก Google Earth มากรอก โปรแกรมจะคำนวณเป็นไร่ให้อัตโนมัติ
A2: หรือถ้าทราบเป็น "ไร่" สามารถกรอกข้อมูลช่อง B2 ได้เลย | B2: =B1/1600 -> 0 | C2: ไร่
A4: 2. กรอกข้อมูลพื้นที่ปลูกพืชนอกอาคาร พื้นที่สวนดาดฟ้า/หลังคา และพื้นที่แหล่งน้ำ โดยดิจิไทซ์ (digitize) จาก Google Earth Pro หากมีหลายผืน สามารถทยอยดิจิไทซ์ กรอกข้อมูล โปรแกรมจะรวมพื้นที่ย่อย ๆ ให้โดยอัตโนมัติในชีทสรุปข้อมูล
A5: ลำดับ | B5: ประเภทพื้นที่ | C5: ขนาดพื้นที่ (ตร.ม.) | D5: ขนาดพื้นที่ (ไร่) | E5: หมายเหตุ
A6: 1 | B6: ยังไม่บันทึกข้อมูล | D6: =C6/1600 -> 0 | F6: ดูตัวเลขพื้นที่สรุป ได้ใน แผ่นงาน "1สรุปข้อมูลพื้นฐาน"
A7: 2 | B7: ยังไม่บันทึกข้อมูล | D7: =C7/1600 -> 0
A8: 3 | B8: ยังไม่บันทึกข้อมูล | D8: =C8/1600 -> 0
A9: 4 | B9: ยังไม่บันทึกข้อมูล | D9: =C9/1600 -> 0
A10: 5 | B10: ยังไม่บันทึกข้อมูล | D10: =C10/1600 -> 0
A11: 6 | B11: ยังไม่บันทึกข้อมูล | D11: =C11/1600 -> 0
A12: 7 | B12: ยังไม่บันทึกข้อมูล | D12: =C12/1600 -> 0
A13: 8 | B13: ยังไม่บันทึกข้อมูล | D13: =C13/1600 -> 0
A14: 9 | B14: ยังไม่บันทึกข้อมูล | D14: =C14/1600 -> 0
A15: 10 | B15: ยังไม่บันทึกข้อมูล | D15: =C15/1600 -> 0
A16: 11 | B16: ยังไม่บันทึกข้อมูล | D16: =C16/1600 -> 0
A17: 12 | B17: ยังไม่บันทึกข้อมูล | D17: =C17/1600 -> 0
A18: 13 | B18: ยังไม่บันทึกข้อมูล | D18: =C18/1600 -> 0
... A155: 150 | B155: ยังไม่บันทึกข้อมูล | D155: =C155/1600 -> 0

Sheet 3พื้นที่เรือนยอด
A1: กรอกข้อมูลพื้นที่ที่ปกคลุมด้วยเรือนยอดของไม้ต้น ปาล์ม และไผ่
A2: ลำดับ | B2: ขนาดพื้นที่ปกคลุม ด้วยเรือนยอด (ตร.ม.) | C2: ขนาดพื้นที่ปกคลุม ด้วยเรือนยอด (ไร่) | D2: หมายเหตุ
A3: 1 | C3: =B3/1600 -> 0
A4: 2 | C4: =B4/1600 -> 0
A5: 3 | C5: =B5/1600 -> 0
A6: 4 | C6: =B6/1600 -> 0
A7: 5 | C7: =B7/1600 -> 0
A8: 6 | C8: =B8/1600 -> 0
A9: 7 | C9: =B9/1600 -> 0
A10: 8 | C10: =B10/1600 -> 0
A11: 9 | C11: =B11/1600 -> 0
A12: 10 | C12: =B12/1600 -> 0
A13: 11 | C13: =B13/1600 -> 0
A14: 12 | C14: =B14/1600 -> 0
... A102: 100 | C102: =B102/1600 -> 0

Sheet 4ข้อมูลไม้ต้น (ปัจจุบัน)
C2: ปี พ.ศ.ที่เก็บข้อมูล | F2: (ปัจจุบัน)
C3: ขนาดพื้นที่แปลง หรือพื้นที่เก็บตัวอย่าง | F3: ไร่ | H3: ไม้ต้น (พืชที่มีเนื้อไม้ มีเส้นผ่านศูนย์กลางที่ระดับความสูงเพียงอก (130 ซม.จากระดับพื้นดิน) ตั้งแต่ 4.5 ซม. ขึ้นไป และมีความสูง ตั้งแต่ 1.3 ม. ขึ้นไป) | X3: =SUM(X6:X1005) -> 0
A5: ลำดับ | B5: แปลงที่ | C5: ต้นที่ | D5: นางที่ (ลำต้นที่) | E5: ชื่อต้นไม้_ชื่อไทย | F5: พิกัดUTM_X_E | G5: พิกัดUTM_Y_N | H5: เส้นรอบวงที่ ระดับอก (ซม.) | I5: หมายเหตุ การวัดเส้นรอบวง | J5: เส้นผ่านศูนย์กลาง ที่ระดับอก (ซม.) | K5: ความสูงที่ได้จากไคลโนมิเตอร์ ที่อ่านค่าความสูงได้เลย (ม.) (ห่าง 10 ม. จากต้นไม้) | L5: ความสูงถึงระดับ สายตาของผู้วัด (ม.) | M5: ความสูงต้นไม้ทั้งต้น กรณีวัดความสูงได้ (ม.) ไม่ได้ใช้ไคลโนมิเตอร์ | N5: สรุปความสูงต้นไม้ (ม.) | O5: มวลชีวภาพเหนือพื้นดินส่วนลําต้น (กก.) | P5: มวลชีวภาพเหนือพื้นดินส่วนกิ่ง (กก.) | Q5: มวลชีวภาพเหนือพื้นดินส่วนใบ (กก.) | R5: มวลชีวภาพ เหนือพื้นดินรวม (กก.) | S5: มวลชีวภาพ ใต้ดินรวม (กก.) | T5: มวลชีวภาพรวม (กก.) | U5: ปริมาณคาร์บอนสะสม (carbon storage) จากมวลชีวภาพเหนือพื้นดิน (กก.คาร์บอน) | V5: ปริมาณคาร์บอนสะสม (carbon storage) จากมวลชีวภาพใต้ดิน (กก.คาร์บอน) | W5: ปริมาณคาร์บอนสะสมรวม (ตัน คาร์บอน) | X5: ปริมาณCO2ดูดซับรวมรายต้น (ตันคาร์บอนไดออกไซด์เทียบเท่า) | Y5: หมายเหตุ | Z5: ชื่อวิทยาศาสตร์ | AA5: วิสัย
A6: 1 | B6: 1 | C6: 1 | D6: 1 | J6: =IF(H6="","รอข้อมูลคอลัมน์ H", IF(H6/PI()>=4.5,H6/PI(),"ไม่ใช่ไม้ต้น ไม่นำมาคำนวณ")) -> รอข้อมูลคอลัมน์ H | N6: {=IF(AND(K6:M6=""),"ยังไม่บันทึกข้อมูล", IF(M6<>"", IF(M6>=1.3,M6,"เป็นไม้พุ่ม"), IF(K6+L6>=1.3,K6+L6,"เป็นไม้พุ่ม")))} -> ยังไม่บันทึกข้อมูล | O6: =IF(AND(ISNUMBER(J6),ISNUMBER(N6)),0.0396*(((J6)^2)*N6)^0.933,"ข้อมูลไม่ถูกต้อง") -> ข้อมูลไม่ถูกต้อง | P6: =IF(AND(ISNUMBER(J6),ISNUMBER(N6)),0.00349*(((J6^2)*N6))^1.03,"ข้อมูลไม่ถูกต้อง") -> ข้อมูลไม่ถูกต้อง | Q6: =IF(AND(ISNUMBER(O6),ISNUMBER(P6)),((1/(28/(O6+P6)))+0.025),"ข้อมูลไม่ถูกต้อง") -> ข้อมูลไม่ถูกต้อง | R6: =IF(AND(O6<>"ข้อมูลไม่ถูกต้อง",P6<>"ข้อมูลไม่ถูกต้อง",Q6<>"ข้อมูลไม่ถูกต้อง"),O6+P6+Q6,"ข้อมูลไม่ถูกต้อง") -> ข้อมูลไม่ถูกต้อง | S6: =IF(ISNUMBER(R6), IF(H$2=ตัวเลือก!A$30,"ยังไม่บันทึกข้อมูล",R6*0.27),"ข้อมูลไม่ถูกต้อง") -> ข้อมูลไม่ถูกต้อง | T6: =IF(AND(ISNUMBER(R6),ISNUMBER(S6)),R6+S6,"ข้อมูลไม่ถูกต้อง") -> ข้อมูลไม่ถูกต้อง | U6: =IF(ISNUMBER(R6), IF(H$2=ตัวเลือก!A$30,"ยังไม่บันทึกข้อมูล",R6*0.47),"ข้อมูลไม่ถูกต้อง") -> ข้อมูลไม่ถูกต้อง | V6: =IF(ISNUMBER(S6), IF(H$2=ตัวเลือก!A$30,"ยังไม่บันทึกข้อมูล",S6*0.47),"ข้อมูลไม่ถูกต้อง") -> ข้อมูลไม่ถูกต้อง | W6: =IF(AND(ISNUMBER(U6),ISNUMBER(V6)),((U6+V6)/1000),"ข้อมูลไม่ถูกต้อง") -> ข้อมูลไม่ถูกต้อง | X6: =IF(ISNUMBER(W6),W6*(44/12),"ข้อมูลไม่ถูกต้อง") -> ข้อมูลไม่ถูกต้อง
A7: 2 | B7: 1 | D7: 2 | J7: =IF(H7="","รอข้อมูลคอลัมน์ H", IF(H7/PI()>=4.5,H7/PI(),"ไม่นำมาคำนวณ")) -> รอข้อมูลคอลัมน์ H | N7: {=IF(AND(K7:M7=""),"ยังไม่บันทึกข้อมูล", IF(M7<>"", IF(M7>=1.3,M7,"เป็นไม้พุ่ม"), IF(K7+L7>=1.3,K7+L7,"เป็นไม้พุ่ม")))} -> ยังไม่บันทึกข้อมูล | O7: =IF(AND(ISNUMBER(J7),ISNUMBER(N7)),0.0396*(((J7)^2)*N7)^0.933,"ข้อมูลไม่ถูกต้อง") -> ข้อมูลไม่ถูกต้อง | P7: =IF(AND(ISNUMBER(J7),ISNUMBER(N7)),0.00349*(((J7^2)*N7))^1.03,"ข้อมูลไม่ถูกต้อง") -> ข้อมูลไม่ถูกต้อง | Q7: =IF(AND(ISNUMBER(O7),ISNUMBER(P7)),((1/(28/(O7+P7)))+0.025),"ข้อมูลไม่ถูกต้อง") -> ข้อมูลไม่ถูกต้อง | R7: =IF(AND(O7<>"ข้อมูลไม่ถูกต้อง",P7<>"ข้อมูลไม่ถูกต้อง",Q7<>"ข้อมูลไม่ถูกต้อง"),O7+P7+Q7,"ข้อมูลไม่ถูกต้อง") -> ข้อมูลไม่ถูกต้อง | S7: =IF(ISNUMBER(R7), IF(H$2=ตัวเลือก!A$30,"ยังไม่บันทึกข้อมูล",R7*0.27),"ข้อมูลไม่ถูกต้อง") -> ข้อมูลไม่ถูกต้อง | T7: =IF(AND(ISNUMBER(R7),ISNUMBER(S7)),R7+S7,"ข้อมูลไม่ถูกต้อง") -> ข้อมูลไม่ถูกต้อง | U7: =IF(ISNUMBER(R7), IF(H$2=ตัวเลือก!A$30,"ยังไม่บันทึกข้อมูล",R7*0.47),"ข้อมูลไม่ถูกต้อง") -> ข้อมูลไม่ถูกต้อง | V7: =IF(ISNUMBER(S7), IF(H$2=ตัวเลือก!A$30,"ยังไม่บันทึกข้อมูล",S7*0.47),"ข้อมูลไม่ถูกต้อง") -> ข้อมูลไม่ถูกต้อง | W7: =IF(AND(ISNUMBER(U7),ISNUMBER(V7)),((U7+V7)/1000),"ข้อมูลไม่ถูกต้อง") -> ข้อมูลไม่ถูกต้อง | X7: =IF(ISNUMBER(W7),W7*(44/12),"ข้อมูลไม่ถูกต้อง") -> ข้อมูลไม่ถูกต้อง
A8: 3 | B8: 1 | D8: 3 | J8: =IF(H8="","รอข้อมูลคอลัมน์ H", IF(H8/PI()>=4.5,H8/PI(),"ไม่นำมาคำนวณ")) -> รอข้อมูลคอลัมน์ H | N8: {=IF(AND(K8:M8=""),"ยังไม่บันทึกข้อมูล", IF(M8<>"", IF(M8>=1.3,M8,"เป็นไม้พุ่ม"), IF(K8+L8>=1.3,K8+L8,"เป็นไม้พุ่ม")))} -> ยังไม่บันทึกข้อมูล | O8: =IF(AND(ISNUMBER(J8),ISNUMBER(N8)),0.0396*(((J8)^2)*N8)^0.933,"ข้อมูลไม่ถูกต้อง") -> ข้อมูลไม่ถูกต้อง | P8: =IF(AND(ISNUMBER(J8),ISNUMBER(N8)),0.00349*(((J8^2)*N8))^1.03,"ข้อมูลไม่ถูกต้อง") -> ข้อมูลไม่ถูกต้อง | Q8: =IF(AND(ISNUMBER(O8),ISNUMBER(P8)),((1/(28/(O8+P8)))+0.025),"ข้อมูลไม่ถูกต้อง") -> ข้อมูลไม่ถูกต้อง | R8: =IF(AND(O8<>"ข้อมูลไม่ถูกต้อง",P8<>"ข้อมูลไม่ถูกต้อง",Q8<>"ข้อมูลไม่ถูกต้อง"),O8+P8+Q8,"ข้อมูลไม่ถูกต้อง") -> ข้อมูลไม่ถูกต้อง | S8: =IF(ISNUMBER(R8), IF(H$2=ตัวเลือก!A$30,"ยังไม่บันทึกข้อมูล",R8*0.27),"ข้อมูลไม่ถูกต้อง") -> ข้อมูลไม่ถูกต้อง | T8: =IF(AND(ISNUMBER(R8),ISNUMBER(S8)),R8+S8,"ข้อมูลไม่ถูกต้อง") -> ข้อมูลไม่ถูกต้อง | U8: =IF(ISNUMBER(R8), IF(H$2=ตัวเลือก!A$30,"ยังไม่บันทึกข้อมูล",R8*0.47),"ข้อมูลไม่ถูกต้อง") -> ข้อมูลไม่ถูกต้อง | V8: =IF(ISNUMBER(S8), IF(H$2=ตัวเลือก!A$30,"ยังไม่บันทึกข้อมูล",S8*0.47),"ข้อมูลไม่ถูกต้อง") -> ข้อมูลไม่ถูกต้อง | W8: =IF(AND(ISNUMBER(U8),ISNUMBER(V8)),((U8+V8)/1000),"ข้อมูลไม่ถูกต้อง") -> ข้อมูลไม่ถูกต้อง | X8: =IF(ISNUMBER(W8),W8*(44/12),"ข้อมูลไม่ถูกต้อง") -> ข้อมูลไม่ถูกต้อง
A9: 4 | B9: 1 | C9: 2 | D9: 1 | J9: =IF(H9="","รอข้อมูลคอลัมน์ H", IF(H9/PI()>=4.5,H9/PI(),"ไม่นำมาคำนวณ")) -> รอข้อมูลคอลัมน์ H | N9: {=IF(AND(K9:M9=""),"ยังไม่บันทึกข้อมูล", IF(M9<>"", IF(M9>=1.3,M9,"เป็นไม้พุ่ม"), IF(K9+L9>=1.3,K9+L9,"เป็นไม้พุ่ม")))} -> ยังไม่บันทึกข้อมูล | O9: =IF(AND(ISNUMBER(J9),ISNUMBER(N9)),0.0396*(((J9)^2)*N9)^0.933,"ข้อมูลไม่ถูกต้อง") -> ข้อมูลไม่ถูกต้อง | P9: =IF(AND(ISNUMBER(J9),ISNUMBER(N9)),0.00349*(((J9^2)*N9))^1.03,"ข้อมูลไม่ถูกต้อง") -> ข้อมูลไม่ถูกต้อง | Q9: =IF(AND(ISNUMBER(O9),ISNUMBER(P9)),((1/(28/(O9+P9)))+0.025),"ข้อมูลไม่ถูกต้อง") -> ข้อมูลไม่ถูกต้อง | R9: =IF(AND(O9<>"ข้อมูลไม่ถูกต้อง",P9<>"ข้อมูลไม่ถูกต้อง",Q9<>"ข้อมูลไม่ถูกต้อง"),O9+P9+Q9,"ข้อมูลไม่ถูกต้อง") -> ข้อมูลไม่ถูกต้อง | S9: =IF(ISNUMBER(R9), IF(H$2=ตัวเลือก!A$30,"ยังไม่บันทึกข้อมูล",R9*0.27),"ข้อมูลไม่ถูกต้อง") -> ข้อมูลไม่ถูกต้อง | T9: =IF(AND(ISNUMBER(R9),ISNUMBER(S9)),R9+S9,"ข้อมูลไม่ถูกต้อง") -> ข้อมูลไม่ถูกต้อง | U9: =IF(ISNUMBER(R9), IF(H$2=ตัวเลือก!A$30,"ยังไม่บันทึกข้อมูล",R9*0.47),"ข้อมูลไม่ถูกต้อง") -> ข้อมูลไม่ถูกต้อง | V9: =IF(ISNUMBER(S9), IF(H$2=ตัวเลือก!A$30,"ยังไม่บันทึกข้อมูล",S9*0.47),"ข้อมูลไม่ถูกต้อง") -> ข้อมูลไม่ถูกต้อง | W9: =IF(AND(ISNUMBER(U9),ISNUMBER(V9)),((U9+V9)/1000),"ข้อมูลไม่ถูกต้อง") -> ข้อมูลไม่ถูกต้อง | X9: =IF(ISNUMBER(W9),W9*(44/12),"ข้อมูลไม่ถูกต้อง") -> ข้อมูลไม่ถูกต้อง
A10: 5 | B10: 1 | D10: 2 | J10: =IF(H10="","รอข้อมูลคอลัมน์ H", IF(H10/PI()>=4.5,H10/PI(),"ไม่นำมาคำนวณ")) -> รอข้อมูลคอลัมน์ H | N10: {=IF(AND(K10:M10=""),"ยังไม่บันทึกข้อมูล", IF(M10<>"", IF(M10>=1.3,M10,"เป็นไม้พุ่ม"), IF(K10+L10>=1.3,K10+L10,"เป็นไม้พุ่ม")))} -> ยังไม่บันทึกข้อมูล | O10: =IF(AND(ISNUMBER(J10),ISNUMBER(N10)),0.0396*(((J10)^2)*N10)^0.933,"ข้อมูลไม่ถูกต้อง") -> ข้อมูลไม่ถูกต้อง | P10: =IF(AND(ISNUMBER(J10),ISNUMBER(N10)),0.00349*(((J10^2)*N10))^1.03,"ข้อมูลไม่ถูกต้อง") -> ข้อมูลไม่ถูกต้อง | Q10: =IF(AND(ISNUMBER(O10),ISNUMBER(P10)),((1/(28/(O10+P10)))+0.025),"ข้อมูลไม่ถูกต้อง") -> ข้อมูลไม่ถูกต้อง | R10: =IF(AND(O10<>"ข้อมูลไม่ถูกต้อง",P10<>"ข้อมูลไม่ถูกต้อง",Q10<>"ข้อมูลไม่ถูกต้อง"),O10+P10+Q10,"ข้อมูลไม่ถูกต้อง") -> ข้อมูลไม่ถูกต้อง | S10: =IF(ISNUMBER(R10), IF(H$2=ตัวเลือก!A$30,"ยังไม่บันทึกข้อมูล",R10*0.27),"ข้อมูลไม่ถูกต้อง") -> ข้อมูลไม่ถูกต้อง | T10: =IF(AND(ISNUMBER(R10),ISNUMBER(S10)),R10+S10,"ข้อมูลไม่ถูกต้อง") -> ข้อมูลไม่ถูกต้อง | U10: =IF(ISNUMBER(R10), IF(H$2=ตัวเลือก!A$30,"ยังไม่บันทึกข้อมูล",R10*0.47),"ข้อมูลไม่ถูกต้อง") -> ข้อมูลไม่ถูกต้อง | V10: =IF(ISNUMBER(S10), IF(H$2=ตัวเลือก!A$30,"ยังไม่บันทึกข้อมูล",S10*0.47),"ข้อมูลไม่ถูกต้อง") -> ข้อมูลไม่ถูกต้อง | W10: =IF(AND(ISNUMBER(U10),ISNUMBER(V10)),((U10+V10)/1000),"ข้อมูลไม่ถูกต้อง") -> ข้อมูลไม่ถูกต้อง | X10: =IF(ISNUMBER(W10),W10*(44/12),"ข้อมูลไม่ถูกต้อง") -> ข้อมูลไม่ถูกต้อง
A11: 6 | B11: 1 | C11: 3 | D11: 1 | J11: =IF(H11="","รอข้อมูลคอลัมน์ H", IF(H11/PI()>=4.5,H11/PI(),"ไม่นำมาคำนวณ")) -> รอข้อมูลคอลัมน์ H | N11: {=IF(AND(K11:M11=""),"ยังไม่บันทึกข้อมูล", IF(M11<>"", IF(M11>=1.3,M11,"เป็นไม้พุ่ม"), IF(K11+L11>=1.3,K11+L11,"เป็นไม้พุ่ม")))} -> ยังไม่บันทึกข้อมูล | O11: =IF(AND(ISNUMBER(J11),ISNUMBER(N11)),0.0396*(((J11)^2)*N11)^0.933,"ข้อมูลไม่ถูกต้อง") -> ข้อมูลไม่ถูกต้อง | P11: =IF(AND(ISNUMBER(J11),ISNUMBER(N11)),0.00349*(((J11^2)*N11))^1.03,"ข้อมูลไม่ถูกต้อง") -> ข้อมูลไม่ถูกต้อง | Q11: =IF(AND(ISNUMBER(O11),ISNUMBER(P11)),((1/(28/(O11+P11)))+0.025),"ข้อมูลไม่ถูกต้อง") -> ข้อมูลไม่ถูกต้อง | R11: =IF(AND(O11<>"ข้อมูลไม่ถูกต้อง",P11<>"ข้อมูลไม่ถูกต้อง",Q11<>"ข้อมูลไม่ถูกต้อง"),O11+P11+Q11,"ข้อมูลไม่ถูกต้อง") -> ข้อมูลไม่ถูกต้อง | S11: =IF(ISNUMBER(R11), IF(H$2=ตัวเลือก!A$30,"ยังไม่บันทึกข้อมูล",R11*0.27),"ข้อมูลไม่ถูกต้อง") -> ข้อมูลไม่ถูกต้อง | T11: =IF(AND(ISNUMBER(R11),ISNUMBER(S11)),R11+S11,"ข้อมูลไม่ถูกต้อง") -> ข้อมูลไม่ถูกต้อง | U11: =IF(ISNUMBER(R11), IF(H$2=ตัวเลือก!A$30,"ยังไม่บันทึกข้อมูล",R11*0.47),"ข้อมูลไม่ถูกต้อง") -> ข้อมูลไม่ถูกต้อง | V11: =IF(ISNUMBER(S11), IF(H$2=ตัวเลือก!A$30,"ยังไม่บันทึกข้อมูล",S11*0.47),"ข้อมูลไม่ถูกต้อง") -> ข้อมูลไม่ถูกต้อง | W11: =IF(AND(ISNUMBER(U11),ISNUMBER(V11)),((U11+V11)/1000),"ข้อมูลไม่ถูกต้อง") -> ข้อมูลไม่ถูกต้อง | X11: =IF(ISNUMBER(W11),W11*(44/12),"ข้อมูลไม่ถูกต้อง") -> ข้อมูลไม่ถูกต้อง
A12: 7 | B12: 1 | D12: 2 | J12: =IF(H12="","รอข้อมูลคอลัมน์ H", IF(H12/PI()>=4.5,H12/PI(),"ไม่นำมาคำนวณ")) -> รอข้อมูลคอลัมน์ H | N12: {=IF(AND(K12:M12=""),"ยังไม่บันทึกข้อมูล", IF(M12<>"", IF(M12>=1.3,M12,"เป็นไม้พุ่ม"), IF(K12+L12>=1.3,K12+L12,"เป็นไม้พุ่ม")))} -> ยังไม่บันทึกข้อมูล | O12: =IF(AND(ISNUMBER(J12),ISNUMBER(N12)),0.0396*(((J12)^2)*N12)^0.933,"ข้อมูลไม่ถูกต้อง") -> ข้อมูลไม่ถูกต้อง | P12: =IF(AND(ISNUMBER(J12),ISNUMBER(N12)),0.00349*(((J12^2)*N12))^1.03,"ข้อมูลไม่ถูกต้อง") -> ข้อมูลไม่ถูกต้อง | Q12: =IF(AND(ISNUMBER(O12),ISNUMBER(P12)),((1/(28/(O12+P12)))+0.025),"ข้อมูลไม่ถูกต้อง") -> ข้อมูลไม่ถูกต้อง | R12: =IF(AND(O12<>"ข้อมูลไม่ถูกต้อง",P12<>"ข้อมูลไม่ถูกต้อง",Q12<>"ข้อมูลไม่ถูกต้อง"),O12+P12+Q12,"ข้อมูลไม่ถูกต้อง") -> ข้อมูลไม่ถูกต้อง | S12: =IF(ISNUMBER(R12), IF(H$2=ตัวเลือก!A$30,"ยังไม่บันทึกข้อมูล",R12*0.27),"ข้อมูลไม่ถูกต้อง") -> ข้อมูลไม่ถูกต้อง | T12: =IF(AND(ISNUMBER(R12),ISNUMBER(S12)),R12+S12,"ข้อมูลไม่ถูกต้อง") -> ข้อมูลไม่ถูกต้อง | U12: =IF(ISNUMBER(R12), IF(H$2=ตัวเลือก!A$30,"ยังไม่บันทึกข้อมูล",R12*0.47),"ข้อมูลไม่ถูกต้อง") -> ข้อมูลไม่ถูกต้อง | V12: =IF(ISNUMBER(S12), IF(H$2=ตัวเลือก!A$30,"ยังไม่บันทึกข้อมูล",S12*0.47),"ข้อมูลไม่ถูกต้อง") -> ข้อมูลไม่ถูกต้อง | W12: =IF(AND(ISNUMBER(U12),ISNUMBER(V12)),((U12+V12)/1000),"ข้อมูลไม่ถูกต้อง") -> ข้อมูลไม่ถูกต้อง | X12: =IF(ISNUMBER(W12),W12*(44/12),"ข้อมูลไม่ถูกต้อง") -> ข้อมูลไม่ถูกต้อง
A13: 8 | B13: 1 | D13: 3 | J13: =IF(H13="","รอข้อมูลคอลัมน์ H", IF(H13/PI()>=4.5,H13/PI(),"ไม่นำมาคำนวณ")) -> รอข้อมูลคอลัมน์ H | N13: {=IF(AND(K13:M13=""),"ยังไม่บันทึกข้อมูล", IF(M13<>"", IF(M13>=1.3,M13,"เป็นไม้พุ่ม"), IF(K13+L13>=1.3,K13+L13,"เป็นไม้พุ่ม")))} -> ยังไม่บันทึกข้อมูล | O13: =IF(AND(ISNUMBER(J13),ISNUMBER(N13)),0.0396*(((J13)^2)*N13)^0.933,"ข้อมูลไม่ถูกต้อง") -> ข้อมูลไม่ถูกต้อง | P13: =IF(AND(ISNUMBER(J13),ISNUMBER(N13)),0.00349*(((J13^2)*N13))^1.03,"ข้อมูลไม่ถูกต้อง") -> ข้อมูลไม่ถูกต้อง | Q13: =IF(AND(ISNUMBER(O13),ISNUMBER(P13)),((1/(28/(O13+P13)))+0.025),"ข้อมูลไม่ถูกต้อง") -> ข้อมูลไม่ถูกต้อง | R13: =IF(AND(O13<>"ข้อมูลไม่ถูกต้อง",P13<>"ข้อมูลไม่ถูกต้อง",Q13<>"ข้อมูลไม่ถูกต้อง"),O13+P13+Q13,"ข้อมูลไม่ถูกต้อง") -> ข้อมูลไม่ถูกต้อง | S13: =IF(ISNUMBER(R13), IF(H$2=ตัวเลือก!A$30,"ยังไม่บันทึกข้อมูล",R13*0.27),"ข้อมูลไม่ถูกต้อง") -> ข้อมูลไม่ถูกต้อง | T13: =IF(AND(ISNUMBER(R13),ISNUMBER(S13)),R13+S13,"ข้อมูลไม่ถูกต้อง") -> ข้อมูลไม่ถูกต้อง | U13: =IF(ISNUMBER(R13), IF(H$2=ตัวเลือก!A$30,"ยังไม่บันทึกข้อมูล",R13*0.47),"ข้อมูลไม่ถูกต้อง") -> ข้อมูลไม่ถูกต้อง | V13: =IF(ISNUMBER(S13), IF(H$2=ตัวเลือก!A$30,"ยังไม่บันทึกข้อมูล",S13*0.47),"ข้อมูลไม่ถูกต้อง") -> ข้อมูลไม่ถูกต้อง | W13: =IF(AND(ISNUMBER(U13),ISNUMBER(V13)),((U13+V13)/1000),"ข้อมูลไม่ถูกต้อง") -> ข้อมูลไม่ถูกต้อง | X13: =IF(ISNUMBER(W13),W13*(44/12),"ข้อมูลไม่ถูกต้อง") -> ข้อมูลไม่ถูกต้อง
A14: 9 | B14: 1 | D14: 4 | J14: =IF(H14="","รอข้อมูลคอลัมน์ H", IF(H14/PI()>=4.5,H14/PI(),"ไม่นำมาคำนวณ")) -> รอข้อมูลคอลัมน์ H | N14: {=IF(AND(K14:M14=""),"ยังไม่บันทึกข้อมูล", IF(M14<>"", IF(M14>=1.3,M14,"เป็นไม้พุ่ม"), IF(K14+L14>=1.3,K14+L14,"เป็นไม้พุ่ม")))} -> ยังไม่บันทึกข้อมูล | O14: =IF(AND(ISNUMBER(J14),ISNUMBER(N14)),0.0396*(((J14)^2)*N14)^0.933,"ข้อมูลไม่ถูกต้อง") -> ข้อมูลไม่ถูกต้อง | P14: =IF(AND(ISNUMBER(J14),ISNUMBER(N14)),0.00349*(((J14^2)*N14))^1.03,"ข้อมูลไม่ถูกต้อง") -> ข้อมูลไม่ถูกต้อง | Q14: =IF(AND(ISNUMBER(O14),ISNUMBER(P14)),((1/(28/(O14+P14)))+0.025),"ข้อมูลไม่ถูกต้อง") -> ข้อมูลไม่ถูกต้อง | R14: =IF(AND(O14<>"ข้อมูลไม่ถูกต้อง",P14<>"ข้อมูลไม่ถูกต้อง",Q14<>"ข้อมูลไม่ถูกต้อง"),O14+P14+Q14,"ข้อมูลไม่ถูกต้อง") -> ข้อมูลไม่ถูกต้อง | S14: =IF(ISNUMBER(R14), IF(H$2=ตัวเลือก!A$30,"ยังไม่บันทึกข้อมูล",R14*0.27),"ข้อมูลไม่ถูกต้อง") -> ข้อมูลไม่ถูกต้อง | T14: =IF(AND(ISNUMBER(R14),ISNUMBER(S14)),R14+S14,"ข้อมูลไม่ถูกต้อง") -> ข้อมูลไม่ถูกต้อง | U14: =IF(ISNUMBER(R14), IF(H$2=ตัวเลือก!A$30,"ยังไม่บันทึกข้อมูล",R14*0.47),"ข้อมูลไม่ถูกต้อง") -> ข้อมูลไม่ถูกต้อง | V14: =IF(ISNUMBER(S14), IF(H$2=ตัวเลือก!A$30,"ยังไม่บันทึกข้อมูล",S14*0.47),"ข้อมูลไม่ถูกต้อง") -> ข้อมูลไม่ถูกต้อง | W14: =IF(AND(ISNUMBER(U14),ISNUMBER(V14)),((U14+V14)/1000),"ข้อมูลไม่ถูกต้อง") -> ข้อมูลไม่ถูกต้อง | X14: =IF(ISNUMBER(W14),W14*(44/12),"ข้อมูลไม่ถูกต้อง") -> ข้อมูลไม่ถูกต้อง
A15: 10 | B15: 1 | D15: 5 | J15: =IF(H15="","รอข้อมูลคอลัมน์ H", IF(H15/PI()>=4.5,H15/PI(),"ไม่นำมาคำนวณ")) -> รอข้อมูลคอลัมน์ H | N15: {=IF(AND(K15:M15=""),"ยังไม่บันทึกข้อมูล", IF(M15<>"", IF(M15>=1.3,M15,"เป็นไม้พุ่ม"), IF(K15+L15>=1.3,K15+L15,"เป็นไม้พุ่ม")))} -> ยังไม่บันทึกข้อมูล | O15: =IF(AND(ISNUMBER(J15),ISNUMBER(N15)),0.0396*(((J15)^2)*N15)^0.933,"ข้อมูลไม่ถูกต้อง") -> ข้อมูลไม่ถูกต้อง | P15: =IF(AND(ISNUMBER(J15),ISNUMBER(N15)),0.00349*(((J15^2)*N15))^1.03,"ข้อมูลไม่ถูกต้อง") -> ข้อมูลไม่ถูกต้อง | Q15: =IF(AND(ISNUMBER(O15),ISNUMBER(P15)),((1/(28/(O15+P15)))+0.025),"ข้อมูลไม่ถูกต้อง") -> ข้อมูลไม่ถูกต้อง | R15: =IF(AND(O15<>"ข้อมูลไม่ถูกต้อง",P15<>"ข้อมูลไม่ถูกต้อง",Q15<>"ข้อมูลไม่ถูกต้อง"),O15+P15+Q15,"ข้อมูลไม่ถูกต้อง") -> ข้อมูลไม่ถูกต้อง | S15: =IF(ISNUMBER(R15), IF(H$2=ตัวเลือก!A$30,"ยังไม่บันทึกข้อมูล",R15*0.27),"ข้อมูลไม่ถูกต้อง") -> ข้อมูลไม่ถูกต้อง | T15: =IF(AND(ISNUMBER(R15),ISNUMBER(S15)),R15+S15,"ข้อมูลไม่ถูกต้อง") -> ข้อมูลไม่ถูกต้อง | U15: =IF(ISNUMBER(R15), IF(H$2=ตัวเลือก!A$30,"ยังไม่บันทึกข้อมูล",R15*0.47),"ข้อมูลไม่ถูกต้อง") -> ข้อมูลไม่ถูกต้อง | V15: =IF(ISNUMBER(S15), IF(H$2=ตัวเลือก!A$30,"ยังไม่บันทึกข้อมูล",S15*0.47),"ข้อมูลไม่ถูกต้อง") -> ข้อมูลไม่ถูกต้อง | W15: =IF(AND(ISNUMBER(U15),ISNUMBER(V15)),((U15+V15)/1000),"ข้อมูลไม่ถูกต้อง") -> ข้อมูลไม่ถูกต้อง | X15: =IF(ISNUMBER(W15),W15*(44/12),"ข้อมูลไม่ถูกต้อง") -> ข้อมูลไม่ถูกต้อง
A16: 11 | B16: 1 | J16: =IF(H16="","รอข้อมูลคอลัมน์ H", IF(H16/PI()>=4.5,H16/PI(),"ไม่นำมาคำนวณ")) -> รอข้อมูลคอลัมน์ H | N16: {=IF(AND(K16:M16=""),"ยังไม่บันทึกข้อมูล", IF(M16<>"", IF(M16>=1.3,M16,"เป็นไม้พุ่ม"), IF(K16+L16>=1.3,K16+L16,"เป็นไม้พุ่ม")))} -> ยังไม่บันทึกข้อมูล | O16: =IF(AND(ISNUMBER(J16),ISNUMBER(N16)),0.0396*(((J16)^2)*N16)^0.933,"ข้อมูลไม่ถูกต้อง") -> ข้อมูลไม่ถูกต้อง | P16: =IF(AND(ISNUMBER(J16),ISNUMBER(N16)),0.00349*(((J16^2)*N16))^1.03,"ข้อมูลไม่ถูกต้อง") -> ข้อมูลไม่ถูกต้อง | Q16: =IF(AND(ISNUMBER(O16),ISNUMBER(P16)),((1/(28/(O16+P16)))+0.025),"ข้อมูลไม่ถูกต้อง") -> ข้อมูลไม่ถูกต้อง | R16: =IF(AND(O16<>"ข้อมูลไม่ถูกต้อง",P16<>"ข้อมูลไม่ถูกต้อง",Q16<>"ข้อมูลไม่ถูกต้อง"),O16+P16+Q16,"ข้อมูลไม่ถูกต้อง") -> ข้อมูลไม่ถูกต้อง | S16: =IF(ISNUMBER(R16), IF(H$2=ตัวเลือก!A$30,"ยังไม่บันทึกข้อมูล",R16*0.27),"ข้อมูลไม่ถูกต้อง") -> ข้อมูลไม่ถูกต้อง | T16: =IF(AND(ISNUMBER(R16),ISNUMBER(S16)),R16+S16,"ข้อมูลไม่ถูกต้อง") -> ข้อมูลไม่ถูกต้อง | U16: =IF(ISNUMBER(R16), IF(H$2=ตัวเลือก!A$30,"ยังไม่บันทึกข้อมูล",R16*0.47),"ข้อมูลไม่ถูกต้อง") -> ข้อมูลไม่ถูกต้อง | V16: =IF(ISNUMBER(S16), IF(H$2=ตัวเลือก!A$30,"ยังไม่บันทึกข้อมูล",S16*0.47),"ข้อมูลไม่ถูกต้อง") -> ข้อมูลไม่ถูกต้อง | W16: =IF(AND(ISNUMBER(U16),ISNUMBER(V16)),((U16+V16)/1000),"ข้อมูลไม่ถูกต้อง") -> ข้อมูลไม่ถูกต้อง | X16: =IF(ISNUMBER(W16),W16*(44/12),"ข้อมูลไม่ถูกต้อง") -> ข้อมูลไม่ถูกต้อง
A17: 12 | B17: 1 | J17: =IF(H17="","รอข้อมูลคอลัมน์ H", IF(H17/PI()>=4.5,H17/PI(),"ไม่นำมาคำนวณ")) -> รอข้อมูลคอลัมน์ H | N17: {=IF(AND(K17:M17=""),"ยังไม่บันทึกข้อมูล", IF(M17<>"", IF(M17>=1.3,M17,"เป็นไม้พุ่ม"), IF(K17+L17>=1.3,K17+L17,"เป็นไม้พุ่ม")))} -> ยังไม่บันทึกข้อมูล | O17: =IF(AND(ISNUMBER(J17),ISNUMBER(N17)),0.0396*(((J17)^2)*N17)^0.933,"ข้อมูลไม่ถูกต้อง") -> ข้อมูลไม่ถูกต้อง | P17: =IF(AND(ISNUMBER(J17),ISNUMBER(N17)),0.00349*(((J17^2)*N17))^1.03,"ข้อมูลไม่ถูกต้อง") -> ข้อมูลไม่ถูกต้อง | Q17: =IF(AND(ISNUMBER(O17),ISNUMBER(P17)),((1/(28/(O17+P17)))+0.025),"ข้อมูลไม่ถูกต้อง") -> ข้อมูลไม่ถูกต้อง | R17: =IF(AND(O17<>"ข้อมูลไม่ถูกต้อง",P17<>"ข้อมูลไม่ถูกต้อง",Q17<>"ข้อมูลไม่ถูกต้อง"),O17+P17+Q17,"ข้อมูลไม่ถูกต้อง") -> ข้อมูลไม่ถูกต้อง | S17: =IF(ISNUMBER(R17), IF(H$2=ตัวเลือก!A$30,"ยังไม่บันทึกข้อมูล",R17*0.27),"ข้อมูลไม่ถูกต้อง") -> ข้อมูลไม่ถูกต้อง | T17: =IF(AND(ISNUMBER(R17),ISNUMBER(S17)),R17+S17,"ข้อมูลไม่ถูกต้อง") -> ข้อมูลไม่ถูกต้อง | U17: =IF(ISNUMBER(R17), IF(H$2=ตัวเลือก!A$30,"ยังไม่บันทึกข้อมูล",R17*0.47),"ข้อมูลไม่ถูกต้อง") -> ข้อมูลไม่ถูกต้อง | V17: =IF(ISNUMBER(S17), IF(H$2=ตัวเลือก!A$30,"ยังไม่บันทึกข้อมูล",S17*0.47),"ข้อมูลไม่ถูกต้อง") -> ข้อมูลไม่ถูกต้อง | W17: =IF(AND(ISNUMBER(U17),ISNUMBER(V17)),((U17+V17)/1000),"ข้อมูลไม่ถูกต้อง") -> ข้อมูลไม่ถูกต้อง | X17: =IF(ISNUMBER(W17),W17*(44/12),"ข้อมูลไม่ถูกต้อง") -> ข้อมูลไม่ถูกต้อง
A18: 13 | B18: 1 | J18: =IF(H18="","รอข้อมูลคอลัมน์ H", IF(H18/PI()>=4.5,H18/PI(),"ไม่นำมาคำนวณ")) -> รอข้อมูลคอลัมน์ H | N18: {=IF(AND(K18:M18=""),"ยังไม่บันทึกข้อมูล", IF(M18<>"", IF(M18>=1.3,M18,"เป็นไม้พุ่ม"), IF(K18+L18>=1.3,K18+L18,"เป็นไม้พุ่ม")))} -> ยังไม่บันทึกข้อมูล | O18: =IF(AND(ISNUMBER(J18),ISNUMBER(N18)),0.0396*(((J18)^2)*N18)^0.933,"ข้อมูลไม่ถูกต้อง") -> ข้อมูลไม่ถูกต้อง | P18: =IF(AND(ISNUMBER(J18),ISNUMBER(N18)),0.00349*(((J18^2)*N18))^1.03,"ข้อมูลไม่ถูกต้อง") -> ข้อมูลไม่ถูกต้อง | Q18: =IF(AND(ISNUMBER(O18),ISNUMBER(P18)),((1/(28/(O18+P18)))+0.025),"ข้อมูลไม่ถูกต้อง") -> ข้อมูลไม่ถูกต้อง | R18: =IF(AND(O18<>"ข้อมูลไม่ถูกต้อง",P18<>"ข้อมูลไม่ถูกต้อง",Q18<>"ข้อมูลไม่ถูกต้อง"),O18+P18+Q18,"ข้อมูลไม่ถูกต้อง") -> ข้อมูลไม่ถูกต้อง | S18: =IF(ISNUMBER(R18), IF(H$2=ตัวเลือก!A$30,"ยังไม่บันทึกข้อมูล",R18*0.27),"ข้อมูลไม่ถูกต้อง") -> ข้อมูลไม่ถูกต้อง | T18: =IF(AND(ISNUMBER(R18),ISNUMBER(S18)),R18+S18,"ข้อมูลไม่ถูกต้อง") -> ข้อมูลไม่ถูกต้อง | U18: =IF(ISNUMBER(R18), IF(H$2=ตัวเลือก!A$30,"ยังไม่บันทึกข้อมูล",R18*0.47),"ข้อมูลไม่ถูกต้อง") -> ข้อมูลไม่ถูกต้อง | V18: =IF(ISNUMBER(S18), IF(H$2=ตัวเลือก!A$30,"ยังไม่บันทึกข้อมูล",S18*0.47),"ข้อมูลไม่ถูกต้อง") -> ข้อมูลไม่ถูกต้อง | W18: =IF(AND(ISNUMBER(U18),ISNUMBER(V18)),((U18+V18)/1000),"ข้อมูลไม่ถูกต้อง") -> ข้อมูลไม่ถูกต้อง | X18: =IF(ISNUMBER(W18),W18*(44/12),"ข้อมูลไม่ถูกต้อง") -> ข้อมูลไม่ถูกต้อง
A19: 14 | B19: 1 | J19: =IF(H19="","รอข้อมูลคอลัมน์ H", IF(H19/PI()>=4.5,H19/PI(),"ไม่นำมาคำนวณ")) -> รอข้อมูลคอลัมน์ H | N19: {=IF(AND(K19:M19=""),"ยังไม่บันทึกข้อมูล", IF(M19<>"", IF(M19>=1.3,M19,"เป็นไม้พุ่ม"), IF(K19+L19>=1.3,K19+L19,"เป็นไม้พุ่ม")))} -> ยังไม่บันทึกข้อมูล | O19: =IF(AND(ISNUMBER(J19),ISNUMBER(N19)),0.0396*(((J19)^2)*N19)^0.933,"ข้อมูลไม่ถูกต้อง") -> ข้อมูลไม่ถูกต้อง | P19: =IF(AND(ISNUMBER(J19),ISNUMBER(N19)),0.00349*(((J19^2)*N19))^1.03,"ข้อมูลไม่ถูกต้อง") -> ข้อมูลไม่ถูกต้อง | Q19: =IF(AND(ISNUMBER(O19),ISNUMBER(P19)),((1/(28/(O19+P19)))+0.025),"ข้อมูลไม่ถูกต้อง") -> ข้อมูลไม่ถูกต้อง | R19: =IF(AND(O19<>"ข้อมูลไม่ถูกต้อง",P19<>"ข้อมูลไม่ถูกต้อง",Q19<>"ข้อมูลไม่ถูกต้อง"),O19+P19+Q19,"ข้อมูลไม่ถูกต้อง") -> ข้อมูลไม่ถูกต้อง | S19: =IF(ISNUMBER(R19), IF(H$2=ตัวเลือก!A$30,"ยังไม่บันทึกข้อมูล",R19*0.27),"ข้อมูลไม่ถูกต้อง") -> ข้อมูลไม่ถูกต้อง | T19: =IF(AND(ISNUMBER(R19),ISNUMBER(S19)),R19+S19,"ข้อมูลไม่ถูกต้อง") -> ข้อมูลไม่ถูกต้อง | U19: =IF(ISNUMBER(R19), IF(H$2=ตัวเลือก!A$30,"ยังไม่บันทึกข้อมูล",R19*0.47),"ข้อมูลไม่ถูกต้อง") -> ข้อมูลไม่ถูกต้อง | V19: =IF(ISNUMBER(S19), IF(H$2=ตัวเลือก!A$30,"ยังไม่บันทึกข้อมูล",S19*0.47),"ข้อมูลไม่ถูกต้อง") -> ข้อมูลไม่ถูกต้อง | W19: =IF(AND(ISNUMBER(U19),ISNUMBER(V19)),((U19+V19)/1000),"ข้อมูลไม่ถูกต้อง") -> ข้อมูลไม่ถูกต้อง | X19: =IF(ISNUMBER(W19),W19*(44/12),"ข้อมูลไม่ถูกต้อง") -> ข้อมูลไม่ถูกต้อง
A20: 15 | B20: 1 | J20: =IF(H20="","รอข้อมูลคอลัมน์ H", IF(H20/PI()>=4.5,H20/PI(),"ไม่นำมาคำนวณ")) -> รอข้อมูลคอลัมน์ H | N20: {=IF(AND(K20:M20=""),"ยังไม่บันทึกข้อมูล", IF(M20<>"", IF(M20>=1.3,M20,"เป็นไม้พุ่ม"), IF(K20+L20>=1.3,K20+L20,"เป็นไม้พุ่ม")))} -> ยังไม่บันทึกข้อมูล | O20: =IF(AND(ISNUMBER(J20),ISNUMBER(N20)),0.0396*(((J20)^2)*N20)^0.933,"ข้อมูลไม่ถูกต้อง") -> ข้อมูลไม่ถูกต้อง | P20: =IF(AND(ISNUMBER(J20),ISNUMBER(N20)),0.00349*(((J20^2)*N20))^1.03,"ข้อมูลไม่ถูกต้อง") -> ข้อมูลไม่ถูกต้อง | Q20: =IF(AND(ISNUMBER(O20),ISNUMBER(P20)),((1/(28/(O20+P20)))+0.025),"ข้อมูลไม่ถูกต้อง") -> ข้อมูลไม่ถูกต้อง | R20: =IF(AND(O20<>"ข้อมูลไม่ถูกต้อง",P20<>"ข้อมูลไม่ถูกต้อง",Q20<>"ข้อมูลไม่ถูกต้อง"),O20+P20+Q20,"ข้อมูลไม่ถูกต้อง") -> ข้อมูลไม่ถูกต้อง | S20: =IF(ISNUMBER(R20), IF(H$2=ตัวเลือก!A$30,"ยังไม่บันทึกข้อมูล",R20*0.27),"ข้อมูลไม่ถูกต้อง") -> ข้อมูลไม่ถูกต้อง | T20: =IF(AND(ISNUMBER(R20),ISNUMBER(S20)),R20+S20,"ข้อมูลไม่ถูกต้อง") -> ข้อมูลไม่ถูกต้อง | U20: =IF(ISNUMBER(R20), IF(H$2=ตัวเลือก!A$30,"ยังไม่บันทึกข้อมูล",R20*0.47),"ข้อมูลไม่ถูกต้อง") -> ข้อมูลไม่ถูกต้อง | V20: =IF(ISNUMBER(S20), IF(H$2=ตัวเลือก!A$30,"ยังไม่บันทึกข้อมูล",S20*0.47),"ข้อมูลไม่ถูกต้อง") -> ข้อมูลไม่ถูกต้อง | W20: =IF(AND(ISNUMBER(U20),ISNUMBER(V20)),((U20+V20)/1000),"ข้อมูลไม่ถูกต้อง") -> ข้อมูลไม่ถูกต้อง | X20: =IF(ISNUMBER(W20),W20*(44/12),"ข้อมูลไม่ถูกต้อง") -> ข้อมูลไม่ถูกต้อง
A21: 16 | B21: 1 | J21: =IF(H21="","รอข้อมูลคอลัมน์ H", IF(H21/PI()>=4.5,H21/PI(),"ไม่นำมาคำนวณ")) -> รอข้อมูลคอลัมน์ H | N21: {=IF(AND(K21:M21=""),"ยังไม่บันทึกข้อมูล", IF(M21<>"", IF(M21>=1.3,M21,"เป็นไม้พุ่ม"), IF(K21+L21>=1.3,K21+L21,"เป็นไม้พุ่ม")))} -> ยังไม่บันทึกข้อมูล | O21: =IF(AND(ISNUMBER(J21),ISNUMBER(N21)),0.0396*(((J21)^2)*N21)^0.933,"ข้อมูลไม่ถูกต้อง") -> ข้อมูลไม่ถูกต้อง | P21: =IF(AND(ISNUMBER(J21),ISNUMBER(N21)),0.00349*(((J21^2)*N21))^1.03,"ข้อมูลไม่ถูกต้อง") -> ข้อมูลไม่ถูกต้อง | Q21: =IF(AND(ISNUMBER(O21),ISNUMBER(P21)),((1/(28/(O21+P21)))+0.025),"ข้อมูลไม่ถูกต้อง") -> ข้อมูลไม่ถูกต้อง | R21: =IF(AND(O21<>"ข้อมูลไม่ถูกต้อง",P21<>"ข้อมูลไม่ถูกต้อง",Q21<>"ข้อมูลไม่ถูกต้อง"),O21+P21+Q21,"ข้อมูลไม่ถูกต้อง") -> ข้อมูลไม่ถูกต้อง | S21: =IF(ISNUMBER(R21), IF(H$2=ตัวเลือก!A$30,"ยังไม่บันทึกข้อมูล",R21*0.27),"ข้อมูลไม่ถูกต้อง") -> ข้อมูลไม่ถูกต้อง | T21: =IF(AND(ISNUMBER(R21),ISNUMBER(S21)),R21+S21,"ข้อมูลไม่ถูกต้อง") -> ข้อมูลไม่ถูกต้อง | U21: =IF(ISNUMBER(R21), IF(H$2=ตัวเลือก!A$30,"ยังไม่บันทึกข้อมูล",R21*0.47),"ข้อมูลไม่ถูกต้อง") -> ข้อมูลไม่ถูกต้อง | V21: =IF(ISNUMBER(S21), IF(H$2=ตัวเลือก!A$30,"ยังไม่บันทึกข้อมูล",S21*0.47),"ข้อมูลไม่ถูกต้อง") -> ข้อมูลไม่ถูกต้อง | W21: =IF(AND(ISNUMBER(U21),ISNUMBER(V21)),((U21+V21)/1000),"ข้อมูลไม่ถูกต้อง") -> ข้อมูลไม่ถูกต้อง | X21: =IF(ISNUMBER(W21),W21*(44/12),"ข้อมูลไม่ถูกต้อง") -> ข้อมูลไม่ถูกต้อง
A22: 17 | B22: 1 | J22: =IF(H22="","รอข้อมูลคอลัมน์ H", IF(H22/PI()>=4.5,H22/PI(),"ไม่นำมาคำนวณ")) -> รอข้อมูลคอลัมน์ H | N22: {=IF(AND(K22:M22=""),"ยังไม่บันทึกข้อมูล", IF(M22<>"", IF(M22>=1.3,M22,"เป็นไม้พุ่ม"), IF(K22+L22>=1.3,K22+L22,"เป็นไม้พุ่ม")))} -> ยังไม่บันทึกข้อมูล | O22: =IF(AND(ISNUMBER(J22),ISNUMBER(N22)),0.0396*(((J22)^2)*N22)^0.933,"ข้อมูลไม่ถูกต้อง") -> ข้อมูลไม่ถูกต้อง | P22: =IF(AND(ISNUMBER(J22),ISNUMBER(N22)),0.00349*(((J22^2)*N22))^1.03,"ข้อมูลไม่ถูกต้อง") -> ข้อมูลไม่ถูกต้อง | Q22: =IF(AND(ISNUMBER(O22),ISNUMBER(P22)),((1/(28/(O22+P22)))+0.025),"ข้อมูลไม่ถูกต้อง") -> ข้อมูลไม่ถูกต้อง | R22: =IF(AND(O22<>"ข้อมูลไม่ถูกต้อง",P22<>"ข้อมูลไม่ถูกต้อง",Q22<>"ข้อมูลไม่ถูกต้อง"),O22+P22+Q22,"ข้อมูลไม่ถูกต้อง") -> ข้อมูลไม่ถูกต้อง | S22: =IF(ISNUMBER(R22), IF(H$2=ตัวเลือก!A$30,"ยังไม่บันทึกข้อมูล",R22*0.27),"ข้อมูลไม่ถูกต้อง") -> ข้อมูลไม่ถูกต้อง | T22: =IF(AND(ISNUMBER(R22),ISNUMBER(S22)),R22+S22,"ข้อมูลไม่ถูกต้อง") -> ข้อมูลไม่ถูกต้อง | U22: =IF(ISNUMBER(R22), IF(H$2=ตัวเลือก!A$30,"ยังไม่บันทึกข้อมูล",R22*0.47),"ข้อมูลไม่ถูกต้อง") -> ข้อมูลไม่ถูกต้อง | V22: =IF(ISNUMBER(S22), IF(H$2=ตัวเลือก!A$30,"ยังไม่บันทึกข้อมูล",S22*0.47),"ข้อมูลไม่ถูกต้อง") -> ข้อมูลไม่ถูกต้อง | W22: =IF(AND(ISNUMBER(U22),ISNUMBER(V22)),((U22+V22)/1000),"ข้อมูลไม่ถูกต้อง") -> ข้อมูลไม่ถูกต้อง | X22: =IF(ISNUMBER(W22),W22*(44/12),"ข้อมูลไม่ถูกต้อง") -> ข้อมูลไม่ถูกต้อง
A23: 18 | B23: 1 | J23: =IF(H23="","รอข้อมูลคอลัมน์ H", IF(H23/PI()>=4.5,H23/PI(),"ไม่นำมาคำนวณ")) -> รอข้อมูลคอลัมน์ H | N23: {=IF(AND(K23:M23=""),"ยังไม่บันทึกข้อมูล", IF(M23<>"", IF(M23>=1.3,M23,"เป็นไม้พุ่ม"), IF(K23+L23>=1.3,K23+L23,"เป็นไม้พุ่ม")))} -> ยังไม่บันทึกข้อมูล | O23: =IF(AND(ISNUMBER(J23),ISNUMBER(N23)),0.0396*(((J23)^2)*N23)^0.933,"ข้อมูลไม่ถูกต้อง") -> ข้อมูลไม่ถูกต้อง | P23: =IF(AND(ISNUMBER(J23),ISNUMBER(N23)),0.00349*(((J23^2)*N23))^1.03,"ข้อมูลไม่ถูกต้อง") -> ข้อมูลไม่ถูกต้อง | Q23: =IF(AND(ISNUMBER(O23),ISNUMBER(P23)),((1/(28/(O23+P23)))+0.025),"ข้อมูลไม่ถูกต้อง") -> ข้อมูลไม่ถูกต้อง | R23: =IF(AND(O23<>"ข้อมูลไม่ถูกต้อง",P23<>"ข้อมูลไม่ถูกต้อง",Q23<>"ข้อมูลไม่ถูกต้อง"),O23+P23+Q23,"ข้อมูลไม่ถูกต้อง") -> ข้อมูลไม่ถูกต้อง | S23: =IF(ISNUMBER(R23), IF(H$2=ตัวเลือก!A$30,"ยังไม่บันทึกข้อมูล",R23*0.27),"ข้อมูลไม่ถูกต้อง") -> ข้อมูลไม่ถูกต้อง | T23: =IF(AND(ISNUMBER(R23),ISNUMBER(S23)),R23+S23,"ข้อมูลไม่ถูกต้อง") -> ข้อมูลไม่ถูกต้อง | U23: =IF(ISNUMBER(R23), IF(H$2=ตัวเลือก!A$30,"ยังไม่บันทึกข้อมูล",R23*0.47),"ข้อมูลไม่ถูกต้อง") -> ข้อมูลไม่ถูกต้อง | V23: =IF(ISNUMBER(S23), IF(H$2=ตัวเลือก!A$30,"ยังไม่บันทึกข้อมูล",S23*0.47),"ข้อมูลไม่ถูกต้อง") -> ข้อมูลไม่ถูกต้อง | W23: =IF(AND(ISNUMBER(U23),ISNUMBER(V23)),((U23+V23)/1000),"ข้อมูลไม่ถูกต้อง") -> ข้อมูลไม่ถูกต้อง | X23: =IF(ISNUMBER(W23),W23*(44/12),"ข้อมูลไม่ถูกต้อง") -> ข้อมูลไม่ถูกต้อง
A24: 19 | B24: 1 | J24: =IF(H24="","รอข้อมูลคอลัมน์ H", IF(H24/PI()>=4.5,H24/PI(),"ไม่นำมาคำนวณ")) -> รอข้อมูลคอลัมน์ H | N24: {=IF(AND(K24:M24=""),"ยังไม่บันทึกข้อมูล", IF(M24<>"", IF(M24>=1.3,M24,"เป็นไม้พุ่ม"), IF(K24+L24>=1.3,K24+L24,"เป็นไม้พุ่ม")))} -> ยังไม่บันทึกข้อมูล | O24: =IF(AND(ISNUMBER(J24),ISNUMBER(N24)),0.0396*(((J24)^2)*N24)^0.933,"ข้อมูลไม่ถูกต้อง") -> ข้อมูลไม่ถูกต้อง | P24: =IF(AND(ISNUMBER(J24),ISNUMBER(N24)),0.00349*(((J24^2)*N24))^1.03,"ข้อมูลไม่ถูกต้อง") -> ข้อมูลไม่ถูกต้อง | Q24: =IF(AND(ISNUMBER(O24),ISNUMBER(P24)),((1/(28/(O24+P24)))+0.025),"ข้อมูลไม่ถูกต้อง") -> ข้อมูลไม่ถูกต้อง | R24: =IF(AND(O24<>"ข้อมูลไม่ถูกต้อง",P24<>"ข้อมูลไม่ถูกต้อง",Q24<>"ข้อมูลไม่ถูกต้อง"),O24+P24+Q24,"ข้อมูลไม่ถูกต้อง") -> ข้อมูลไม่ถูกต้อง | S24: =IF(ISNUMBER(R24), IF(H$2=ตัวเลือก!A$30,"ยังไม่บันทึกข้อมูล",R24*0.27),"ข้อมูลไม่ถูกต้อง") -> ข้อมูลไม่ถูกต้อง | T24: =IF(AND(ISNUMBER(R24),ISNUMBER(S24)),R24+S24,"ข้อมูลไม่ถูกต้อง") -> ข้อมูลไม่ถูกต้อง | U24: =IF(ISNUMBER(R24), IF(H$2=ตัวเลือก!A$30,"ยังไม่บันทึกข้อมูล",R24*0.47),"ข้อมูลไม่ถูกต้อง") -> ข้อมูลไม่ถูกต้อง | V24: =IF(ISNUMBER(S24), IF(H$2=ตัวเลือก!A$30,"ยังไม่บันทึกข้อมูล",S24*0.47),"ข้อมูลไม่ถูกต้อง") -> ข้อมูลไม่ถูกต้อง | W24: =IF(AND(ISNUMBER(U24),ISNUMBER(V24)),((U24+V24)/1000),"ข้อมูลไม่ถูกต้อง") -> ข้อมูลไม่ถูกต้อง | X24: =IF(ISNUMBER(W24),W24*(44/12),"ข้อมูลไม่ถูกต้อง") -> ข้อมูลไม่ถูกต้อง
A25: 20 | B25: 1 | J25: =IF(H25="","รอข้อมูลคอลัมน์ H", IF(H25/PI()>=4.5,H25/PI(),"ไม่นำมาคำนวณ")) -> รอข้อมูลคอลัมน์ H | N25: {=IF(AND(K25:M25=""),"ยังไม่บันทึกข้อมูล", IF(M25<>"", IF(M25>=1.3,M25,"เป็นไม้พุ่ม"), IF(K25+L25>=1.3,K25+L25,"เป็นไม้พุ่ม")))} -> ยังไม่บันทึกข้อมูล | O25: =IF(AND(ISNUMBER(J25),ISNUMBER(N25)),0.0396*(((J25)^2)*N25)^0.933,"ข้อมูลไม่ถูกต้อง") -> ข้อมูลไม่ถูกต้อง | P25: =IF(AND(ISNUMBER(J25),ISNUMBER(N25)),0.00349*(((J25^2)*N25))^1.03,"ข้อมูลไม่ถูกต้อง") -> ข้อมูลไม่ถูกต้อง | Q25: =IF(AND(ISNUMBER(O25),ISNUMBER(P25)),((1/(28/(O25+P25)))+0.025),"ข้อมูลไม่ถูกต้อง") -> ข้อมูลไม่ถูกต้อง | R25: =IF(AND(O25<>"ข้อมูลไม่ถูกต้อง",P25<>"ข้อมูลไม่ถูกต้อง",Q25<>"ข้อมูลไม่ถูกต้อง"),O25+P25+Q25,"ข้อมูลไม่ถูกต้อง") -> ข้อมูลไม่ถูกต้อง | S25: =IF(ISNUMBER(R25), IF(H$2=ตัวเลือก!A$30,"ยังไม่บันทึกข้อมูล",R25*0.27),"ข้อมูลไม่ถูกต้อง") -> ข้อมูลไม่ถูกต้อง | T25: =IF(AND(ISNUMBER(R25),ISNUMBER(S25)),R25+S25,"ข้อมูลไม่ถูกต้อง") -> ข้อมูลไม่ถูกต้อง | U25: =IF(ISNUMBER(R25), IF(H$2=ตัวเลือก!A$30,"ยังไม่บันทึกข้อมูล",R25*0.47),"ข้อมูลไม่ถูกต้อง") -> ข้อมูลไม่ถูกต้อง | V25: =IF(ISNUMBER(S25), IF(H$2=ตัวเลือก!A$30,"ยังไม่บันทึกข้อมูล",S25*0.47),"ข้อมูลไม่ถูกต้อง") -> ข้อมูลไม่ถูกต้อง | W25: =IF(AND(ISNUMBER(U25),ISNUMBER(V25)),((U25+V25)/1000),"ข้อมูลไม่ถูกต้อง") -> ข้อมูลไม่ถูกต้อง | X25: =IF(ISNUMBER(W25),W25*(44/12),"ข้อมูลไม่ถูกต้อง") -> ข้อมูลไม่ถูกต้อง
A26: 21 | B26: 1 | J26: =IF(H26="","รอข้อมูลคอลัมน์ H", IF(H26/PI()>=4.5,H26/PI(),"ไม่นำมาคำนวณ")) -> รอข้อมูลคอลัมน์ H | N26: {=IF(AND(K26:M26=""),"ยังไม่บันทึกข้อมูล", IF(M26<>"", IF(M26>=1.3,M26,"เป็นไม้พุ่ม"), IF(K26+L26>=1.3,K26+L26,"เป็นไม้พุ่ม")))} -> ยังไม่บันทึกข้อมูล | O26: =IF(AND(ISNUMBER(J26),ISNUMBER(N26)),0.0396*(((J26)^2)*N26)^0.933,"ข้อมูลไม่ถูกต้อง") -> ข้อมูลไม่ถูกต้อง | P26: =IF(AND(ISNUMBER(J26),ISNUMBER(N26)),0.00349*(((J26^2)*N26))^1.03,"ข้อมูลไม่ถูกต้อง") -> ข้อมูลไม่ถูกต้อง | Q26: =IF(AND(ISNUMBER(O26),ISNUMBER(P26)),((1/(28/(O26+P26)))+0.025),"ข้อมูลไม่ถูกต้อง") -> ข้อมูลไม่ถูกต้อง | R26: =IF(AND(O26<>"ข้อมูลไม่ถูกต้อง",P26<>"ข้อมูลไม่ถูกต้อง",Q26<>"ข้อมูลไม่ถูกต้อง"),O26+P26+Q26,"ข้อมูลไม่ถูกต้อง") -> ข้อมูลไม่ถูกต้อง | S26: =IF(ISNUMBER(R26), IF(H$2=ตัวเลือก!A$30,"ยังไม่บันทึกข้อมูล",R26*0.27),"ข้อมูลไม่ถูกต้อง") -> ข้อมูลไม่ถูกต้อง | T26: =IF(AND(ISNUMBER(R26),ISNUMBER(S26)),R26+S26,"ข้อมูลไม่ถูกต้อง") -> ข้อมูลไม่ถูกต้อง | U26: =IF(ISNUMBER(R26), IF(H$2=ตัวเลือก!A$30,"ยังไม่บันทึกข้อมูล",R26*0.47),"ข้อมูลไม่ถูกต้อง") -> ข้อมูลไม่ถูกต้อง | V26: =IF(ISNUMBER(S26), IF(H$2=ตัวเลือก!A$30,"ยังไม่บันทึกข้อมูล",S26*0.47),"ข้อมูลไม่ถูกต้อง") -> ข้อมูลไม่ถูกต้อง | W26: =IF(AND(ISNUMBER(U26),ISNUMBER(V26)),((U26+V26)/1000),"ข้อมูลไม่ถูกต้อง") -> ข้อมูลไม่ถูกต้อง | X26: =IF(ISNUMBER(W26),W26*(44/12),"ข้อมูลไม่ถูกต้อง") -> ข้อมูลไม่ถูกต้อง
A27: 22 | B27: 1 | J27: =IF(H27="","รอข้อมูลคอลัมน์ H", IF(H27/PI()>=4.5,H27/PI(),"ไม่นำมาคำนวณ")) -> รอข้อมูลคอลัมน์ H | N27: {=IF(AND(K27:M27=""),"ยังไม่บันทึกข้อมูล", IF(M27<>"", IF(M27>=1.3,M27,"เป็นไม้พุ่ม"), IF(K27+L27>=1.3,K27+L27,"เป็นไม้พุ่ม")))} -> ยังไม่บันทึกข้อมูล | O27: =IF(AND(ISNUMBER(J27),ISNUMBER(N27)),0.0396*(((J27)^2)*N27)^0.933,"ข้อมูลไม่ถูกต้อง") -> ข้อมูลไม่ถูกต้อง | P27: =IF(AND(ISNUMBER(J27),ISNUMBER(N27)),0.00349*(((J27^2)*N27))^1.03,"ข้อมูลไม่ถูกต้อง") -> ข้อมูลไม่ถูกต้อง | Q27: =IF(AND(ISNUMBER(O27),ISNUMBER(P27)),((1/(28/(O27+P27)))+0.025),"ข้อมูลไม่ถูกต้อง") -> ข้อมูลไม่ถูกต้อง | R27: =IF(AND(O27<>"ข้อมูลไม่ถูกต้อง",P27<>"ข้อมูลไม่ถูกต้อง",Q27<>"ข้อมูลไม่ถูกต้อง"),O27+P27+Q27,"ข้อมูลไม่ถูกต้อง") -> ข้อมูลไม่ถูกต้อง | S27: =IF(ISNUMBER(R27), IF(H$2=ตัวเลือก!A$30,"ยังไม่บันทึกข้อมูล",R27*0.27),"ข้อมูลไม่ถูกต้อง") -> ข้อมูลไม่ถูกต้อง | T27: =IF(AND(ISNUMBER(R27),ISNUMBER(S27)),R27+S27,"ข้อมูลไม่ถูกต้อง") -> ข้อมูลไม่ถูกต้อง | U27: =IF(ISNUMBER(R27), IF(H$2=ตัวเลือก!A$30,"ยังไม่บันทึกข้อมูล",R27*0.47),"ข้อมูลไม่ถูกต้อง") -> ข้อมูลไม่ถูกต้อง | V27: =IF(ISNUMBER(S27), IF(H$2=ตัวเลือก!A$30,"ยังไม่บันทึกข้อมูล",S27*0.47),"ข้อมูลไม่ถูกต้อง") -> ข้อมูลไม่ถูกต้อง | W27: =IF(AND(ISNUMBER(U27),ISNUMBER(V27)),((U27+V27)/1000),"ข้อมูลไม่ถูกต้อง") -> ข้อมูลไม่ถูกต้อง | X27: =IF(ISNUMBER(W27),W27*(44/12),"ข้อมูลไม่ถูกต้อง") -> ข้อมูลไม่ถูกต้อง
... A45: 40 | B45: 1 | J45: =IF(H45="","รอข้อมูลคอลัมน์ H", IF(H45/PI()>=4.5,H45/PI(),"ไม่นำมาคำนวณ")) -> รอข้อมูลคอลัมน์ H | N45: {=IF(AND(K45:M45=""),"ยังไม่บันทึกข้อมูล", IF(M45<>"", IF(M45>=1.3,M45,"เป็นไม้พุ่ม"), IF(K45+L45>=1.3,K45+L45,"เป็นไม้พุ่ม")))} -> ยังไม่บันทึกข้อมูล | O45: =IF(AND(ISNUMBER(J45),ISNUMBER(N45)),0.0396*(((J45)^2)*N45)^0.933,"ข้อมูลไม่ถูกต้อง") -> ข้อมูลไม่ถูกต้อง | P45: =IF(AND(ISNUMBER(J45),ISNUMBER(N45)),0.00349*(((J45^2)*N45))^1.03,"ข้อมูลไม่ถูกต้อง") -> ข้อมูลไม่ถูกต้อง | Q45: =IF(AND(ISNUMBER(O45),ISNUMBER(P45)),((1/(28/(O45+P45)))+0.025),"ข้อมูลไม่ถูกต้อง") -> ข้อมูลไม่ถูกต้อง | R45: =IF(AND(O45<>"ข้อมูลไม่ถูกต้อง",P45<>"ข้อมูลไม่ถูกต้อง",Q45<>"ข้อมูลไม่ถูกต้อง"),O45+P45+Q45,"ข้อมูลไม่ถูกต้อง") -> ข้อมูลไม่ถูกต้อง | S45: =IF(ISNUMBER(R45), IF(H$2=ตัวเลือก!A$30,"ยังไม่บันทึกข้อมูล",R45*0.27),"ข้อมูลไม่ถูกต้อง") -> ข้อมูลไม่ถูกต้อง | T45: =IF(AND(ISNUMBER(R45),ISNUMBER(S45)),R45+S45,"ข้อมูลไม่ถูกต้อง") -> ข้อมูลไม่ถูกต้อง | U45: =IF(ISNUMBER(R45), IF(H$2=ตัวเลือก!A$30,"ยังไม่บันทึกข้อมูล",R45*0.47),"ข้อมูลไม่ถูกต้อง") -> ข้อมูลไม่ถูกต้อง | V45: =IF(ISNUMBER(S45), IF(H$2=ตัวเลือก!A$30,"ยังไม่บันทึกข้อมูล",S45*0.47),"ข้อมูลไม่ถูกต้อง") -> ข้อมูลไม่ถูกต้อง | W45: =IF(AND(ISNUMBER(U45),ISNUMBER(V45)),((U45+V45)/1000),"ข้อมูลไม่ถูกต้อง") -> ข้อมูลไม่ถูกต้อง | X45: =IF(ISNUMBER(W45),W45*(44/12),"ข้อมูลไม่ถูกต้อง") -> ข้อมูลไม่ถูกต้อง
A46: 41 | J46: =IF(H46="","รอข้อมูลคอลัมน์ H", IF(H46/PI()>=4.5,H46/PI(),"ไม่นำมาคำนวณ")) -> รอข้อมูลคอลัมน์ H | N46: {=IF(AND(K46:M46=""),"ยังไม่บันทึกข้อมูล", IF(M46<>"", IF(M46>=1.3,M46,"เป็นไม้พุ่ม"), IF(K46+L46>=1.3,K46+L46,"เป็นไม้พุ่ม")))} -> ยังไม่บันทึกข้อมูล | O46: =IF(AND(ISNUMBER(J46),ISNUMBER(N46)),0.0396*(((J46)^2)*N46)^0.933,"ข้อมูลไม่ถูกต้อง") -> ข้อมูลไม่ถูกต้อง | P46: =IF(AND(ISNUMBER(J46),ISNUMBER(N46)),0.00349*(((J46^2)*N46))^1.03,"ข้อมูลไม่ถูกต้อง") -> ข้อมูลไม่ถูกต้อง | Q46: =IF(AND(ISNUMBER(O46),ISNUMBER(P46)),((1/(28/(O46+P46)))+0.025),"ข้อมูลไม่ถูกต้อง") -> ข้อมูลไม่ถูกต้อง | R46: =IF(AND(O46<>"ข้อมูลไม่ถูกต้อง",P46<>"ข้อมูลไม่ถูกต้อง",Q46<>"ข้อมูลไม่ถูกต้อง"),O46+P46+Q46,"ข้อมูลไม่ถูกต้อง") -> ข้อมูลไม่ถูกต้อง | S46: =IF(ISNUMBER(R46), IF(H$2=ตัวเลือก!A$30,"ยังไม่บันทึกข้อมูล",R46*0.27),"ข้อมูลไม่ถูกต้อง") -> ข้อมูลไม่ถูกต้อง | T46: =IF(AND(ISNUMBER(R46),ISNUMBER(S46)),R46+S46,"ข้อมูลไม่ถูกต้อง") -> ข้อมูลไม่ถูกต้อง | U46: =IF(ISNUMBER(R46), IF(H$2=ตัวเลือก!A$30,"ยังไม่บันทึกข้อมูล",R46*0.47),"ข้อมูลไม่ถูกต้อง") -> ข้อมูลไม่ถูกต้อง | V46: =IF(ISNUMBER(S46), IF(H$2=ตัวเลือก!A$30,"ยังไม่บันทึกข้อมูล",S46*0.47),"ข้อมูลไม่ถูกต้อง") -> ข้อมูลไม่ถูกต้อง | W46: =IF(AND(ISNUMBER(U46),ISNUMBER(V46)),((U46+V46)/1000),"ข้อมูลไม่ถูกต้อง") -> ข้อมูลไม่ถูกต้อง | X46: =IF(ISNUMBER(W46),W46*(44/12),"ข้อมูลไม่ถูกต้อง") -> ข้อมูลไม่ถูกต้อง
A47: 42 | J47: =IF(H47="","รอข้อมูลคอลัมน์ H", IF(H47/PI()>=4.5,H47/PI(),"ไม่นำมาคำนวณ")) -> รอข้อมูลคอลัมน์ H | N47: {=IF(AND(K47:M47=""),"ยังไม่บันทึกข้อมูล", IF(M47<>"", IF(M47>=1.3,M47,"เป็นไม้พุ่ม"), IF(K47+L47>=1.3,K47+L47,"เป็นไม้พุ่ม")))} -> ยังไม่บันทึกข้อมูล | O47: =IF(AND(ISNUMBER(J47),ISNUMBER(N47)),0.0396*(((J47)^2)*N47)^0.933,"ข้อมูลไม่ถูกต้อง") -> ข้อมูลไม่ถูกต้อง | P47: =IF(AND(ISNUMBER(J47),ISNUMBER(N47)),0.00349*(((J47^2)*N47))^1.03,"ข้อมูลไม่ถูกต้อง") -> ข้อมูลไม่ถูกต้อง | Q47: =IF(AND(ISNUMBER(O47),ISNUMBER(P47)),((1/(28/(O47+P47)))+0.025),"ข้อมูลไม่ถูกต้อง") -> ข้อมูลไม่ถูกต้อง | R47: =IF(AND(O47<>"ข้อมูลไม่ถูกต้อง",P47<>"ข้อมูลไม่ถูกต้อง",Q47<>"ข้อมูลไม่ถูกต้อง"),O47+P47+Q47,"ข้อมูลไม่ถูกต้อง") -> ข้อมูลไม่ถูกต้อง | S47: =IF(ISNUMBER(R47), IF(H$2=ตัวเลือก!A$30,"ยังไม่บันทึกข้อมูล",R47*0.27),"ข้อมูลไม่ถูกต้อง") -> ข้อมูลไม่ถูกต้อง | T47: =IF(AND(ISNUMBER(R47),ISNUMBER(S47)),R47+S47,"ข้อมูลไม่ถูกต้อง") -> ข้อมูลไม่ถูกต้อง | U47: =IF(ISNUMBER(R47), IF(H$2=ตัวเลือก!A$30,"ยังไม่บันทึกข้อมูล",R47*0.47),"ข้อมูลไม่ถูกต้อง") -> ข้อมูลไม่ถูกต้อง | V47: =IF(ISNUMBER(S47), IF(H$2=ตัวเลือก!A$30,"ยังไม่บันทึกข้อมูล",S47*0.47),"ข้อมูลไม่ถูกต้อง") -> ข้อมูลไม่ถูกต้อง | W47: =IF(AND(ISNUMBER(U47),ISNUMBER(V47)),((U47+V47)/1000),"ข้อมูลไม่ถูกต้อง") -> ข้อมูลไม่ถูกต้อง | X47: =IF(ISNUMBER(W47),W47*(44/12),"ข้อมูลไม่ถูกต้อง") -> ข้อมูลไม่ถูกต้อง
A48: 43 | J48: =IF(H48="","รอข้อมูลคอลัมน์ H", IF(H48/PI()>=4.5,H48/PI(),"ไม่นำมาคำนวณ")) -> รอข้อมูลคอลัมน์ H | N48: {=IF(AND(K48:M48=""),"ยังไม่บันทึกข้อมูล", IF(M48<>"", IF(M48>=1.3,M48,"เป็นไม้พุ่ม"), IF(K48+L48>=1.3,K48+L48,"เป็นไม้พุ่ม")))} -> ยังไม่บันทึกข้อมูล | O48: =IF(AND(ISNUMBER(J48),ISNUMBER(N48)),0.0396*(((J48)^2)*N48)^0.933,"ข้อมูลไม่ถูกต้อง") -> ข้อมูลไม่ถูกต้อง | P48: =IF(AND(ISNUMBER(J48),ISNUMBER(N48)),0.00349*(((J48^2)*N48))^1.03,"ข้อมูลไม่ถูกต้อง") -> ข้อมูลไม่ถูกต้อง | Q48: =IF(AND(ISNUMBER(O48),ISNUMBER(P48)),((1/(28/(O48+P48)))+0.025),"ข้อมูลไม่ถูกต้อง") -> ข้อมูลไม่ถูกต้อง | R48: =IF(AND(O48<>"ข้อมูลไม่ถูกต้อง",P48<>"ข้อมูลไม่ถูกต้อง",Q48<>"ข้อมูลไม่ถูกต้อง"),O48+P48+Q48,"ข้อมูลไม่ถูกต้อง") -> ข้อมูลไม่ถูกต้อง | S48: =IF(ISNUMBER(R48), IF(H$2=ตัวเลือก!A$30,"ยังไม่บันทึกข้อมูล",R48*0.27),"ข้อมูลไม่ถูกต้อง") -> ข้อมูลไม่ถูกต้อง | T48: =IF(AND(ISNUMBER(R48),ISNUMBER(S48)),R48+S48,"ข้อมูลไม่ถูกต้อง") -> ข้อมูลไม่ถูกต้อง | U48: =IF(ISNUMBER(R48), IF(H$2=ตัวเลือก!A$30,"ยังไม่บันทึกข้อมูล",R48*0.47),"ข้อมูลไม่ถูกต้อง") -> ข้อมูลไม่ถูกต้อง | V48: =IF(ISNUMBER(S48), IF(H$2=ตัวเลือก!A$30,"ยังไม่บันทึกข้อมูล",S48*0.47),"ข้อมูลไม่ถูกต้อง") -> ข้อมูลไม่ถูกต้อง | W48: =IF(AND(ISNUMBER(U48),ISNUMBER(V48)),((U48+V48)/1000),"ข้อมูลไม่ถูกต้อง") -> ข้อมูลไม่ถูกต้อง | X48: =IF(ISNUMBER(W48),W48*(44/12),"ข้อมูลไม่ถูกต้อง") -> ข้อมูลไม่ถูกต้อง
A49: 44 | J49: =IF(H49="","รอข้อมูลคอลัมน์ H", IF(H49/PI()>=4.5,H49/PI(),"ไม่นำมาคำนวณ")) -> รอข้อมูลคอลัมน์ H | N49: {=IF(AND(K49:M49=""),"ยังไม่บันทึกข้อมูล", IF(M49<>"", IF(M49>=1.3,M49,"เป็นไม้พุ่ม"), IF(K49+L49>=1.3,K49+L49,"เป็นไม้พุ่ม")))} -> ยังไม่บันทึกข้อมูล | O49: =IF(AND(ISNUMBER(J49),ISNUMBER(N49)),0.0396*(((J49)^2)*N49)^0.933,"ข้อมูลไม่ถูกต้อง") -> ข้อมูลไม่ถูกต้อง | P49: =IF(AND(ISNUMBER(J49),ISNUMBER(N49)),0.00349*(((J49^2)*N49))^1.03,"ข้อมูลไม่ถูกต้อง") -> ข้อมูลไม่ถูกต้อง | Q49: =IF(AND(ISNUMBER(O49),ISNUMBER(P49)),((1/(28/(O49+P49)))+0.025),"ข้อมูลไม่ถูกต้อง") -> ข้อมูลไม่ถูกต้อง | R49: =IF(AND(O49<>"ข้อมูลไม่ถูกต้อง",P49<>"ข้อมูลไม่ถูกต้อง",Q49<>"ข้อมูลไม่ถูกต้อง"),O49+P49+Q49,"ข้อมูลไม่ถูกต้อง") -> ข้อมูลไม่ถูกต้อง | S49: =IF(ISNUMBER(R49), IF(H$2=ตัวเลือก!A$30,"ยังไม่บันทึกข้อมูล",R49*0.27),"ข้อมูลไม่ถูกต้อง") -> ข้อมูลไม่ถูกต้อง | T49: =IF(AND(ISNUMBER(R49),ISNUMBER(S49)),R49+S49,"ข้อมูลไม่ถูกต้อง") -> ข้อมูลไม่ถูกต้อง | U49: =IF(ISNUMBER(R49), IF(H$2=ตัวเลือก!A$30,"ยังไม่บันทึกข้อมูล",R49*0.47),"ข้อมูลไม่ถูกต้อง") -> ข้อมูลไม่ถูกต้อง | V49: =IF(ISNUMBER(S49), IF(H$2=ตัวเลือก!A$30,"ยังไม่บันทึกข้อมูล",S49*0.47),"ข้อมูลไม่ถูกต้อง") -> ข้อมูลไม่ถูกต้อง | W49: =IF(AND(ISNUMBER(U49),ISNUMBER(V49)),((U49+V49)/1000),"ข้อมูลไม่ถูกต้อง") -> ข้อมูลไม่ถูกต้อง | X49: =IF(ISNUMBER(W49),W49*(44/12),"ข้อมูลไม่ถูกต้อง") -> ข้อมูลไม่ถูกต้อง
A50: 45 | J50: =IF(H50="","รอข้อมูลคอลัมน์ H", IF(H50/PI()>=4.5,H50/PI(),"ไม่นำมาคำนวณ")) -> รอข้อมูลคอลัมน์ H | N50: {=IF(AND(K50:M50=""),"ยังไม่บันทึกข้อมูล", IF(M50<>"", IF(M50>=1.3,M50,"เป็นไม้พุ่ม"), IF(K50+L50>=1.3,K50+L50,"เป็นไม้พุ่ม")))} -> ยังไม่บันทึกข้อมูล | O50: =IF(AND(ISNUMBER(J50),ISNUMBER(N50)),0.0396*(((J50)^2)*N50)^0.933,"ข้อมูลไม่ถูกต้อง") -> ข้อมูลไม่ถูกต้อง | P50: =IF(AND(ISNUMBER(J50),ISNUMBER(N50)),0.00349*(((J50^2)*N50))^1.03,"ข้อมูลไม่ถูกต้อง") -> ข้อมูลไม่ถูกต้อง | Q50: =IF(AND(ISNUMBER(O50),ISNUMBER(P50)),((1/(28/(O50+P50)))+0.025),"ข้อมูลไม่ถูกต้อง") -> ข้อมูลไม่ถูกต้อง | R50: =IF(AND(O50<>"ข้อมูลไม่ถูกต้อง",P50<>"ข้อมูลไม่ถูกต้อง",Q50<>"ข้อมูลไม่ถูกต้อง"),O50+P50+Q50,"ข้อมูลไม่ถูกต้อง") -> ข้อมูลไม่ถูกต้อง | S50: =IF(ISNUMBER(R50), IF(H$2=ตัวเลือก!A$30,"ยังไม่บันทึกข้อมูล",R50*0.27),"ข้อมูลไม่ถูกต้อง") -> ข้อมูลไม่ถูกต้อง | T50: =IF(AND(ISNUMBER(R50),ISNUMBER(S50)),R50+S50,"ข้อมูลไม่ถูกต้อง") -> ข้อมูลไม่ถูกต้อง | U50: =IF(ISNUMBER(R50), IF(H$2=ตัวเลือก!A$30,"ยังไม่บันทึกข้อมูล",R50*0.47),"ข้อมูลไม่ถูกต้อง") -> ข้อมูลไม่ถูกต้อง | V50: =IF(ISNUMBER(S50), IF(H$2=ตัวเลือก!A$30,"ยังไม่บันทึกข้อมูล",S50*0.47),"ข้อมูลไม่ถูกต้อง") -> ข้อมูลไม่ถูกต้อง | W50: =IF(AND(ISNUMBER(U50),ISNUMBER(V50)),((U50+V50)/1000),"ข้อมูลไม่ถูกต้อง") -> ข้อมูลไม่ถูกต้อง | X50: =IF(ISNUMBER(W50),W50*(44/12),"ข้อมูลไม่ถูกต้อง") -> ข้อมูลไม่ถูกต้อง
A51: 46 | J51: =IF(H51="","รอข้อมูลคอลัมน์ H", IF(H51/PI()>=4.5,H51/PI(),"ไม่นำมาคำนวณ")) -> รอข้อมูลคอลัมน์ H | N51: {=IF(AND(K51:M51=""),"ยังไม่บันทึกข้อมูล", IF(M51<>"", IF(M51>=1.3,M51,"เป็นไม้พุ่ม"), IF(K51+L51>=1.3,K51+L51,"เป็นไม้พุ่ม")))} -> ยังไม่บันทึกข้อมูล | O51: =IF(AND(ISNUMBER(J51),ISNUMBER(N51)),0.0396*(((J51)^2)*N51)^0.933,"ข้อมูลไม่ถูกต้อง") -> ข้อมูลไม่ถูกต้อง | P51: =IF(AND(ISNUMBER(J51),ISNUMBER(N51)),0.00349*(((J51^2)*N51))^1.03,"ข้อมูลไม่ถูกต้อง") -> ข้อมูลไม่ถูกต้อง | Q51: =IF(AND(ISNUMBER(O51),ISNUMBER(P51)),((1/(28/(O51+P51)))+0.025),"ข้อมูลไม่ถูกต้อง") -> ข้อมูลไม่ถูกต้อง | R51: =IF(AND(O51<>"ข้อมูลไม่ถูกต้อง",P51<>"ข้อมูลไม่ถูกต้อง",Q51<>"ข้อมูลไม่ถูกต้อง"),O51+P51+Q51,"ข้อมูลไม่ถูกต้อง") -> ข้อมูลไม่ถูกต้อง | S51: =IF(ISNUMBER(R51), IF(H$2=ตัวเลือก!A$30,"ยังไม่บันทึกข้อมูล",R51*0.27),"ข้อมูลไม่ถูกต้อง") -> ข้อมูลไม่ถูกต้อง | T51: =IF(AND(ISNUMBER(R51),ISNUMBER(S51)),R51+S51,"ข้อมูลไม่ถูกต้อง") -> ข้อมูลไม่ถูกต้อง | U51: =IF(ISNUMBER(R51), IF(H$2=ตัวเลือก!A$30,"ยังไม่บันทึกข้อมูล",R51*0.47),"ข้อมูลไม่ถูกต้อง") -> ข้อมูลไม่ถูกต้อง | V51: =IF(ISNUMBER(S51), IF(H$2=ตัวเลือก!A$30,"ยังไม่บันทึกข้อมูล",S51*0.47),"ข้อมูลไม่ถูกต้อง") -> ข้อมูลไม่ถูกต้อง | W51: =IF(AND(ISNUMBER(U51),ISNUMBER(V51)),((U51+V51)/1000),"ข้อมูลไม่ถูกต้อง") -> ข้อมูลไม่ถูกต้อง | X51: =IF(ISNUMBER(W51),W51*(44/12),"ข้อมูลไม่ถูกต้อง") -> ข้อมูลไม่ถูกต้อง
A52: 47 | J52: =IF(H52="","รอข้อมูลคอลัมน์ H", IF(H52/PI()>=4.5,H52/PI(),"ไม่นำมาคำนวณ")) -> รอข้อมูลคอลัมน์ H | N52: {=IF(AND(K52:M52=""),"ยังไม่บันทึกข้อมูล", IF(M52<>"", IF(M52>=1.3,M52,"เป็นไม้พุ่ม"), IF(K52+L52>=1.3,K52+L52,"เป็นไม้พุ่ม")))} -> ยังไม่บันทึกข้อมูล | O52: =IF(AND(ISNUMBER(J52),ISNUMBER(N52)),0.0396*(((J52)^2)*N52)^0.933,"ข้อมูลไม่ถูกต้อง") -> ข้อมูลไม่ถูกต้อง | P52: =IF(AND(ISNUMBER(J52),ISNUMBER(N52)),0.00349*(((J52^2)*N52))^1.03,"ข้อมูลไม่ถูกต้อง") -> ข้อมูลไม่ถูกต้อง | Q52: =IF(AND(ISNUMBER(O52),ISNUMBER(P52)),((1/(28/(O52+P52)))+0.025),"ข้อมูลไม่ถูกต้อง") -> ข้อมูลไม่ถูกต้อง | R52: =IF(AND(O52<>"ข้อมูลไม่ถูกต้อง",P52<>"ข้อมูลไม่ถูกต้อง",Q52<>"ข้อมูลไม่ถูกต้อง"),O52+P52+Q52,"ข้อมูลไม่ถูกต้อง") -> ข้อมูลไม่ถูกต้อง | S52: =IF(ISNUMBER(R52), IF(H$2=ตัวเลือก!A$30,"ยังไม่บันทึกข้อมูล",R52*0.27),"ข้อมูลไม่ถูกต้อง") -> ข้อมูลไม่ถูกต้อง | T52: =IF(AND(ISNUMBER(R52),ISNUMBER(S52)),R52+S52,"ข้อมูลไม่ถูกต้อง") -> ข้อมูลไม่ถูกต้อง | U52: =IF(ISNUMBER(R52), IF(H$2=ตัวเลือก!A$30,"ยังไม่บันทึกข้อมูล",R52*0.47),"ข้อมูลไม่ถูกต้อง") -> ข้อมูลไม่ถูกต้อง | V52: =IF(ISNUMBER(S52), IF(H$2=ตัวเลือก!A$30,"ยังไม่บันทึกข้อมูล",S52*0.47),"ข้อมูลไม่ถูกต้อง") -> ข้อมูลไม่ถูกต้อง | W52: =IF(AND(ISNUMBER(U52),ISNUMBER(V52)),((U52+V52)/1000),"ข้อมูลไม่ถูกต้อง") -> ข้อมูลไม่ถูกต้อง | X52: =IF(ISNUMBER(W52),W52*(44/12),"ข้อมูลไม่ถูกต้อง") -> ข้อมูลไม่ถูกต้อง
A53: 48 | J53: =IF(H53="","รอข้อมูลคอลัมน์ H", IF(H53/PI()>=4.5,H53/PI(),"ไม่นำมาคำนวณ")) -> รอข้อมูลคอลัมน์ H | N53: {=IF(AND(K53:M53=""),"ยังไม่บันทึกข้อมูล", IF(M53<>"", IF(M53>=1.3,M53,"เป็นไม้พุ่ม"), IF(K53+L53>=1.3,K53+L53,"เป็นไม้พุ่ม")))} -> ยังไม่บันทึกข้อมูล | O53: =IF(AND(ISNUMBER(J53),ISNUMBER(N53)),0.0396*(((J53)^2)*N53)^0.933,"ข้อมูลไม่ถูกต้อง") -> ข้อมูลไม่ถูกต้อง | P53: =IF(AND(ISNUMBER(J53),ISNUMBER(N53)),0.00349*(((J53^2)*N53))^1.03,"ข้อมูลไม่ถูกต้อง") -> ข้อมูลไม่ถูกต้อง | Q53: =IF(AND(ISNUMBER(O53),ISNUMBER(P53)),((1/(28/(O53+P53)))+0.025),"ข้อมูลไม่ถูกต้อง") -> ข้อมูลไม่ถูกต้อง | R53: =IF(AND(O53<>"ข้อมูลไม่ถูกต้อง",P53<>"ข้อมูลไม่ถูกต้อง",Q53<>"ข้อมูลไม่ถูกต้อง"),O53+P53+Q53,"ข้อมูลไม่ถูกต้อง") -> ข้อมูลไม่ถูกต้อง | S53: =IF(ISNUMBER(R53), IF(H$2=ตัวเลือก!A$30,"ยังไม่บันทึกข้อมูล",R53*0.27),"ข้อมูลไม่ถูกต้อง") -> ข้อมูลไม่ถูกต้อง | T53: =IF(AND(ISNUMBER(R53),ISNUMBER(S53)),R53+S53,"ข้อมูลไม่ถูกต้อง") -> ข้อมูลไม่ถูกต้อง | U53: =IF(ISNUMBER(R53), IF(H$2=ตัวเลือก!A$30,"ยังไม่บันทึกข้อมูล",R53*0.47),"ข้อมูลไม่ถูกต้อง") -> ข้อมูลไม่ถูกต้อง | V53: =IF(ISNUMBER(S53), IF(H$2=ตัวเลือก!A$30,"ยังไม่บันทึกข้อมูล",S53*0.47),"ข้อมูลไม่ถูกต้อง") -> ข้อมูลไม่ถูกต้อง | W53: =IF(AND(ISNUMBER(U53),ISNUMBER(V53)),((U53+V53)/1000),"ข้อมูลไม่ถูกต้อง") -> ข้อมูลไม่ถูกต้อง | X53: =IF(ISNUMBER(W53),W53*(44/12),"ข้อมูลไม่ถูกต้อง") -> ข้อมูลไม่ถูกต้อง
A54: 49 | J54: =IF(H54="","รอข้อมูลคอลัมน์ H", IF(H54/PI()>=4.5,H54/PI(),"ไม่นำมาคำนวณ")) -> รอข้อมูลคอลัมน์ H | N54: {=IF(AND(K54:M54=""),"ยังไม่บันทึกข้อมูล", IF(M54<>"", IF(M54>=1.3,M54,"เป็นไม้พุ่ม"), IF(K54+L54>=1.3,K54+L54,"เป็นไม้พุ่ม")))} -> ยังไม่บันทึกข้อมูล | O54: =IF(AND(ISNUMBER(J54),ISNUMBER(N54)),0.0396*(((J54)^2)*N54)^0.933,"ข้อมูลไม่ถูกต้อง") -> ข้อมูลไม่ถูกต้อง | P54: =IF(AND(ISNUMBER(J54),ISNUMBER(N54)),0.00349*(((J54^2)*N54))^1.03,"ข้อมูลไม่ถูกต้อง") -> ข้อมูลไม่ถูกต้อง | Q54: =IF(AND(ISNUMBER(O54),ISNUMBER(P54)),((1/(28/(O54+P54)))+0.025),"ข้อมูลไม่ถูกต้อง") -> ข้อมูลไม่ถูกต้อง | R54: =IF(AND(O54<>"ข้อมูลไม่ถูกต้อง",P54<>"ข้อมูลไม่ถูกต้อง",Q54<>"ข้อมูลไม่ถูกต้อง"),O54+P54+Q54,"ข้อมูลไม่ถูกต้อง") -> ข้อมูลไม่ถูกต้อง | S54: =IF(ISNUMBER(R54), IF(H$2=ตัวเลือก!A$30,"ยังไม่บันทึกข้อมูล",R54*0.27),"ข้อมูลไม่ถูกต้อง") -> ข้อมูลไม่ถูกต้อง | T54: =IF(AND(ISNUMBER(R54),ISNUMBER(S54)),R54+S54,"ข้อมูลไม่ถูกต้อง") -> ข้อมูลไม่ถูกต้อง | U54: =IF(ISNUMBER(R54), IF(H$2=ตัวเลือก!A$30,"ยังไม่บันทึกข้อมูล",R54*0.47),"ข้อมูลไม่ถูกต้อง") -> ข้อมูลไม่ถูกต้อง | V54: =IF(ISNUMBER(S54), IF(H$2=ตัวเลือก!A$30,"ยังไม่บันทึกข้อมูล",S54*0.47),"ข้อมูลไม่ถูกต้อง") -> ข้อมูลไม่ถูกต้อง | W54: =IF(AND(ISNUMBER(U54),ISNUMBER(V54)),((U54+V54)/1000),"ข้อมูลไม่ถูกต้อง") -> ข้อมูลไม่ถูกต้อง | X54: =IF(ISNUMBER(W54),W54*(44/12),"ข้อมูลไม่ถูกต้อง") -> ข้อมูลไม่ถูกต้อง
A55: 50 | J55: =IF(H55="","รอข้อมูลคอลัมน์ H", IF(H55/PI()>=4.5,H55/PI(),"ไม่นำมาคำนวณ")) -> รอข้อมูลคอลัมน์ H | N55: {=IF(AND(K55:M55=""),"ยังไม่บันทึกข้อมูล", IF(M55<>"", IF(M55>=1.3,M55,"เป็นไม้พุ่ม"), IF(K55+L55>=1.3,K55+L55,"เป็นไม้พุ่ม")))} -> ยังไม่บันทึกข้อมูล | O55: =IF(AND(ISNUMBER(J55),ISNUMBER(N55)),0.0396*(((J55)^2)*N55)^0.933,"ข้อมูลไม่ถูกต้อง") -> ข้อมูลไม่ถูกต้อง | P55: =IF(AND(ISNUMBER(J55),ISNUMBER(N55)),0.00349*(((J55^2)*N55))^1.03,"ข้อมูลไม่ถูกต้อง") -> ข้อมูลไม่ถูกต้อง | Q55: =IF(AND(ISNUMBER(O55),ISNUMBER(P55)),((1/(28/(O55+P55)))+0.025),"ข้อมูลไม่ถูกต้อง") -> ข้อมูลไม่ถูกต้อง | R55: =IF(AND(O55<>"ข้อมูลไม่ถูกต้อง",P55<>"ข้อมูลไม่ถูกต้อง",Q55<>"ข้อมูลไม่ถูกต้อง"),O55+P55+Q55,"ข้อมูลไม่ถูกต้อง") -> ข้อมูลไม่ถูกต้อง | S55: =IF(ISNUMBER(R55), IF(H$2=ตัวเลือก!A$30,"ยังไม่บันทึกข้อมูล",R55*0.27),"ข้อมูลไม่ถูกต้อง") -> ข้อมูลไม่ถูกต้อง | T55: =IF(AND(ISNUMBER(R55),ISNUMBER(S55)),R55+S55,"ข้อมูลไม่ถูกต้อง") -> ข้อมูลไม่ถูกต้อง | U55: =IF(ISNUMBER(R55), IF(H$2=ตัวเลือก!A$30,"ยังไม่บันทึกข้อมูล",R55*0.47),"ข้อมูลไม่ถูกต้อง") -> ข้อมูลไม่ถูกต้อง | V55: =IF(ISNUMBER(S55), IF(H$2=ตัวเลือก!A$30,"ยังไม่บันทึกข้อมูล",S55*0.47),"ข้อมูลไม่ถูกต้อง") -> ข้อมูลไม่ถูกต้อง | W55: =IF(AND(ISNUMBER(U55),ISNUMBER(V55)),((U55+V55)/1000),"ข้อมูลไม่ถูกต้อง") -> ข้อมูลไม่ถูกต้อง | X55: =IF(ISNUMBER(W55),W55*(44/12),"ข้อมูลไม่ถูกต้อง") -> ข้อมูลไม่ถูกต้อง
